2016-04-14 10:54:41,963 INFO nodepool.NodePool: Setting building node id: 28225 to delete on startup
2016-04-14 10:54:42,099 INFO nodepool.NodePool: Need to launch 1 d-p-c nodes for jenkins1 on local_01
2016-04-14 10:54:42,142 INFO nodepool.NodeLauncher: Creating server with hostname d-p-c-local_01-28226 in local_01 from image dpc for node id: 28226
2016-04-14 10:55:00,029 INFO nodepool.NodePool: Deleted jenkins node id: 28224
2016-04-14 10:55:00,057 INFO nodepool.NodePool: Deleted node id: 28224
2016-04-14 10:55:01,037 INFO nodepool.NodePool: Deleted jenkins node id: 28225
2016-04-14 10:55:01,066 INFO nodepool.NodePool: Deleted node id: 28225
2016-04-14 10:58:42,161 ERROR nodepool.NodeLauncher: OpenStackCloudException launching node id: 28226 in provider: local_01 error:
Traceback (most recent call last):
  File "/usr/local/lib/python2.7/dist-packages/nodepool/nodepool.py", line 408, in _run
    dt = self.launchNode(session)
  File "/usr/local/lib/python2.7/dist-packages/nodepool/nodepool.py", line 485, in launchNode
    server = self.manager.waitForServer(server, self.launch_timeout)
  File "/usr/local/lib/python2.7/dist-packages/nodepool/provider_manager.py", line 222, in waitForServer
    timeout=timeout)
  File "/usr/local/lib/python2.7/dist-packages/shade/openstackcloud.py", line 3712, in wait_for_server
    wait=True, timeout=remaining_timeout)
  File "/usr/local/lib/python2.7/dist-packages/shade/openstackcloud.py", line 3726, in get_active_server
    extra_data=dict(server=server))
OpenStackCloudException: ('Error in creating the server: No valid host was found. There are not enough hosts available.', {'server': Munch({'OS-EXT-STS:task_state': None, 'addresses': {}, 'image': {u'id': u'5568a9bc-9d2b-4f02-a4d9-2ec8be2ec77a'}, 'networks': {}, 'OS-EXT-STS:vm_state': u'error', 'OS-EXT-SRV-ATTR:instance_name': u'instance-00000437', 'OS-SRV-USG:launched_at': None, 'NAME_ATTR': 'name', 'flavor': {u'id': u'4'}, 'id': u'3b46f5d9-741b-4ccc-86c1-120a77b89e1d', 'cloud': 'defaults', 'user_id': u'2c2a671ce4bd49898cd696a0e8283054', 'OS-DCF:diskConfig': u'MANUAL', 'HUMAN_ID': True, 'accessIPv4': '', 'accessIPv6': '', 'public_v4': '', 'OS-EXT-STS:power_state': 0, 'OS-EXT-AZ:availability_zone': u'', 'config_drive': u'', 'status': u'ERROR', 'updated': u'2016-04-14T02:58:42Z', 'hostId': u'', 'OS-EXT-SRV-ATTR:host': None, 'OS-SRV-USG:terminated_at': None, 'key_name': None, 'public_v6': '', 'request_ids': [], 'private_v4': '', 'OS-EXT-SRV-ATTR:hypervisor_hostname': None, 'name': u'd-p-c-local_01-28226', 'created': u'2016-04-14T02:54:53Z', 'fault': {u'message': u'No valid host was found. There are not enough hosts available.', u'code': 500, u'details': u'  File "/usr/lib/python2.7/dist-packages/nova/conductor/manager.py", line 739, in build_instances\n    request_spec, filter_properties)\n  File "/usr/lib/python2.7/dist-packages/nova/scheduler/utils.py", line 343, in wrapped\n    return func(*args, **kwargs)\n  File "/usr/lib/python2.7/dist-packages/nova/scheduler/client/__init__.py", line 52, in select_destinations\n    context, request_spec, filter_properties)\n  File "/usr/lib/python2.7/dist-packages/nova/scheduler/client/__init__.py", line 37, in __run_method\n    return getattr(self.instance, __name)(*args, **kwargs)\n  File "/usr/lib/python2.7/dist-packages/nova/scheduler/client/query.py", line 34, in select_destinations\n    context, request_spec, filter_properties)\n  File "/usr/lib/python2.7/dist-packages/nova/scheduler/rpcapi.py", line 120, in select_destinations\n    request_spec=request_spec, filter_properties=filter_properties)\n  File "/usr/lib/python2.7/dist-packages/oslo_messaging/rpc/client.py", line 158, in call\n    retry=self.retry)\n  File "/usr/lib/python2.7/dist-packages/oslo_messaging/transport.py", line 90, in _send\n    timeout=timeout, retry=retry)\n  File "/usr/lib/python2.7/dist-packages/oslo_messaging/_drivers/amqpdriver.py", line 533, in send\n    retry=retry)\n  File "/usr/lib/python2.7/dist-packages/oslo_messaging/_drivers/amqpdriver.py", line 524, in _send\n    raise result\n', u'created': u'2016-04-14T02:58:42Z'}, 'region': '', 'x_openstack_request_ids': [], 'os-extended-volumes:volumes_attached': [], 'volumes': [], 'tenant_id': u'3bc6c4940bd74fbe81769ca0f998a7e7', 'metadata': {u'groups': u'["local_01", "dpc"]', u'nodepool': u'{"provider_name": "local_01", "node_id": 28226, "image_name": "dpc"}'}, 'human_id': u'd-p-c-local_01-28226'})}) (Extra: {'server': Munch({'OS-EXT-STS:task_state': None, 'addresses': {}, 'image': {u'id': u'5568a9bc-9d2b-4f02-a4d9-2ec8be2ec77a'}, 'networks': {}, 'OS-EXT-STS:vm_state': u'error', 'OS-EXT-SRV-ATTR:instance_name': u'instance-00000437', 'OS-SRV-USG:launched_at': None, 'NAME_ATTR': 'name', 'flavor': {u'id': u'4'}, 'id': u'3b46f5d9-741b-4ccc-86c1-120a77b89e1d', 'cloud': 'defaults', 'user_id': u'2c2a671ce4bd49898cd696a0e8283054', 'OS-DCF:diskConfig': u'MANUAL', 'HUMAN_ID': True, 'accessIPv4': '', 'accessIPv6': '', 'public_v4': '', 'OS-EXT-STS:power_state': 0, 'OS-EXT-AZ:availability_zone': u'', 'config_drive': u'', 'status': u'ERROR', 'updated': u'2016-04-14T02:58:42Z', 'hostId': u'', 'OS-EXT-SRV-ATTR:host': None, 'OS-SRV-USG:terminated_at': None, 'key_name': None, 'public_v6': '', 'request_ids': [], 'private_v4': '', 'OS-EXT-SRV-ATTR:hypervisor_hostname': None, 'name': u'd-p-c-local_01-28226', 'created': u'2016-04-14T02:54:53Z', 'fault': {u'message': u'No valid host was found. There are not enough hosts available.', u'code': 500, u'details': u'  File "/usr/lib/python2.7/dist-packages/nova/conductor/manager.py", line 739, in build_instances\n    request_spec, filter_properties)\n  File "/usr/lib/python2.7/dist-packages/nova/scheduler/utils.py", line 343, in wrapped\n    return func(*args, **kwargs)\n  File "/usr/lib/python2.7/dist-packages/nova/scheduler/client/__init__.py", line 52, in select_destinations\n    context, request_spec, filter_properties)\n  File "/usr/lib/python2.7/dist-packages/nova/scheduler/client/__init__.py", line 37, in __run_method\n    return getattr(self.instance, __name)(*args, **kwargs)\n  File "/usr/lib/python2.7/dist-packages/nova/scheduler/client/query.py", line 34, in select_destinations\n    context, request_spec, filter_properties)\n  File "/usr/lib/python2.7/dist-packages/nova/scheduler/rpcapi.py", line 120, in select_destinations\n    request_spec=request_spec, filter_properties=filter_properties)\n  File "/usr/lib/python2.7/dist-packages/oslo_messaging/rpc/client.py", line 158, in call\n    retry=self.retry)\n  File "/usr/lib/python2.7/dist-packages/oslo_messaging/transport.py", line 90, in _send\n    timeout=timeout, retry=retry)\n  File "/usr/lib/python2.7/dist-packages/oslo_messaging/_drivers/amqpdriver.py", line 533, in send\n    retry=retry)\n  File "/usr/lib/python2.7/dist-packages/oslo_messaging/_drivers/amqpdriver.py", line 524, in _send\n    raise result\n', u'created': u'2016-04-14T02:58:42Z'}, 'region': '', 'x_openstack_request_ids': [], 'os-extended-volumes:volumes_attached': [], 'volumes': [], 'tenant_id': u'3bc6c4940bd74fbe81769ca0f998a7e7', 'metadata': {u'groups': u'["local_01", "dpc"]', u'nodepool': u'{"provider_name": "local_01", "node_id": 28226, "image_name": "dpc"}'}, 'human_id': u'd-p-c-local_01-28226'})})
2016-04-14 10:58:42,198 INFO nodepool.NodePool: Deleted jenkins node id: 28226
2016-04-14 10:58:43,363 INFO nodepool.NodePool: Need to launch 1 d-p-c nodes for jenkins1 on local_01
2016-04-14 10:58:43,399 INFO nodepool.NodeLauncher: Creating server with hostname d-p-c-local_01-28227 in local_01 from image dpc for node id: 28227
2016-04-14 10:58:49,692 INFO nodepool.NodePool: Deleted node id: 28226
2016-04-14 11:02:38,671 ERROR nodepool.NodeLauncher: OpenStackCloudException launching node id: 28227 in provider: local_01 error:
Traceback (most recent call last):
  File "/usr/local/lib/python2.7/dist-packages/nodepool/nodepool.py", line 408, in _run
    dt = self.launchNode(session)
  File "/usr/local/lib/python2.7/dist-packages/nodepool/nodepool.py", line 485, in launchNode
    server = self.manager.waitForServer(server, self.launch_timeout)
  File "/usr/local/lib/python2.7/dist-packages/nodepool/provider_manager.py", line 222, in waitForServer
    timeout=timeout)
  File "/usr/local/lib/python2.7/dist-packages/shade/openstackcloud.py", line 3712, in wait_for_server
    wait=True, timeout=remaining_timeout)
  File "/usr/local/lib/python2.7/dist-packages/shade/openstackcloud.py", line 3726, in get_active_server
    extra_data=dict(server=server))
OpenStackCloudException: ('Error in creating the server: No valid host was found. There are not enough hosts available.', {'server': Munch({'OS-EXT-STS:task_state': None, 'addresses': {}, 'image': {u'id': u'5568a9bc-9d2b-4f02-a4d9-2ec8be2ec77a'}, 'networks': {}, 'OS-EXT-STS:vm_state': u'error', 'OS-EXT-SRV-ATTR:instance_name': u'instance-0000043a', 'OS-SRV-USG:launched_at': None, 'NAME_ATTR': 'name', 'flavor': {u'id': u'4'}, 'id': u'3b3984fe-a423-4901-be3b-eb403014b901', 'cloud': 'defaults', 'user_id': u'2c2a671ce4bd49898cd696a0e8283054', 'OS-DCF:diskConfig': u'MANUAL', 'HUMAN_ID': True, 'accessIPv4': '', 'accessIPv6': '', 'public_v4': '', 'OS-EXT-STS:power_state': 0, 'OS-EXT-AZ:availability_zone': u'', 'config_drive': u'', 'status': u'ERROR', 'updated': u'2016-04-14T03:02:38Z', 'hostId': u'', 'OS-EXT-SRV-ATTR:host': None, 'OS-SRV-USG:terminated_at': None, 'key_name': None, 'public_v6': '', 'request_ids': [], 'private_v4': '', 'OS-EXT-SRV-ATTR:hypervisor_hostname': None, 'name': u'd-p-c-local_01-28227', 'created': u'2016-04-14T02:58:47Z', 'fault': {u'message': u'No valid host was found. There are not enough hosts available.', u'code': 500, u'details': u'  File "/usr/lib/python2.7/dist-packages/nova/conductor/manager.py", line 739, in build_instances\n    request_spec, filter_properties)\n  File "/usr/lib/python2.7/dist-packages/nova/scheduler/utils.py", line 343, in wrapped\n    return func(*args, **kwargs)\n  File "/usr/lib/python2.7/dist-packages/nova/scheduler/client/__init__.py", line 52, in select_destinations\n    context, request_spec, filter_properties)\n  File "/usr/lib/python2.7/dist-packages/nova/scheduler/client/__init__.py", line 37, in __run_method\n    return getattr(self.instance, __name)(*args, **kwargs)\n  File "/usr/lib/python2.7/dist-packages/nova/scheduler/client/query.py", line 34, in select_destinations\n    context, request_spec, filter_properties)\n  File "/usr/lib/python2.7/dist-packages/nova/scheduler/rpcapi.py", line 120, in select_destinations\n    request_spec=request_spec, filter_properties=filter_properties)\n  File "/usr/lib/python2.7/dist-packages/oslo_messaging/rpc/client.py", line 158, in call\n    retry=self.retry)\n  File "/usr/lib/python2.7/dist-packages/oslo_messaging/transport.py", line 90, in _send\n    timeout=timeout, retry=retry)\n  File "/usr/lib/python2.7/dist-packages/oslo_messaging/_drivers/amqpdriver.py", line 533, in send\n    retry=retry)\n  File "/usr/lib/python2.7/dist-packages/oslo_messaging/_drivers/amqpdriver.py", line 524, in _send\n    raise result\n', u'created': u'2016-04-14T03:02:38Z'}, 'region': '', 'x_openstack_request_ids': [], 'os-extended-volumes:volumes_attached': [], 'volumes': [], 'tenant_id': u'3bc6c4940bd74fbe81769ca0f998a7e7', 'metadata': {u'groups': u'["local_01", "dpc"]', u'nodepool': u'{"provider_name": "local_01", "node_id": 28227, "image_name": "dpc"}'}, 'human_id': u'd-p-c-local_01-28227'})}) (Extra: {'server': Munch({'OS-EXT-STS:task_state': None, 'addresses': {}, 'image': {u'id': u'5568a9bc-9d2b-4f02-a4d9-2ec8be2ec77a'}, 'networks': {}, 'OS-EXT-STS:vm_state': u'error', 'OS-EXT-SRV-ATTR:instance_name': u'instance-0000043a', 'OS-SRV-USG:launched_at': None, 'NAME_ATTR': 'name', 'flavor': {u'id': u'4'}, 'id': u'3b3984fe-a423-4901-be3b-eb403014b901', 'cloud': 'defaults', 'user_id': u'2c2a671ce4bd49898cd696a0e8283054', 'OS-DCF:diskConfig': u'MANUAL', 'HUMAN_ID': True, 'accessIPv4': '', 'accessIPv6': '', 'public_v4': '', 'OS-EXT-STS:power_state': 0, 'OS-EXT-AZ:availability_zone': u'', 'config_drive': u'', 'status': u'ERROR', 'updated': u'2016-04-14T03:02:38Z', 'hostId': u'', 'OS-EXT-SRV-ATTR:host': None, 'OS-SRV-USG:terminated_at': None, 'key_name': None, 'public_v6': '', 'request_ids': [], 'private_v4': '', 'OS-EXT-SRV-ATTR:hypervisor_hostname': None, 'name': u'd-p-c-local_01-28227', 'created': u'2016-04-14T02:58:47Z', 'fault': {u'message': u'No valid host was found. There are not enough hosts available.', u'code': 500, u'details': u'  File "/usr/lib/python2.7/dist-packages/nova/conductor/manager.py", line 739, in build_instances\n    request_spec, filter_properties)\n  File "/usr/lib/python2.7/dist-packages/nova/scheduler/utils.py", line 343, in wrapped\n    return func(*args, **kwargs)\n  File "/usr/lib/python2.7/dist-packages/nova/scheduler/client/__init__.py", line 52, in select_destinations\n    context, request_spec, filter_properties)\n  File "/usr/lib/python2.7/dist-packages/nova/scheduler/client/__init__.py", line 37, in __run_method\n    return getattr(self.instance, __name)(*args, **kwargs)\n  File "/usr/lib/python2.7/dist-packages/nova/scheduler/client/query.py", line 34, in select_destinations\n    context, request_spec, filter_properties)\n  File "/usr/lib/python2.7/dist-packages/nova/scheduler/rpcapi.py", line 120, in select_destinations\n    request_spec=request_spec, filter_properties=filter_properties)\n  File "/usr/lib/python2.7/dist-packages/oslo_messaging/rpc/client.py", line 158, in call\n    retry=self.retry)\n  File "/usr/lib/python2.7/dist-packages/oslo_messaging/transport.py", line 90, in _send\n    timeout=timeout, retry=retry)\n  File "/usr/lib/python2.7/dist-packages/oslo_messaging/_drivers/amqpdriver.py", line 533, in send\n    retry=retry)\n  File "/usr/lib/python2.7/dist-packages/oslo_messaging/_drivers/amqpdriver.py", line 524, in _send\n    raise result\n', u'created': u'2016-04-14T03:02:38Z'}, 'region': '', 'x_openstack_request_ids': [], 'os-extended-volumes:volumes_attached': [], 'volumes': [], 'tenant_id': u'3bc6c4940bd74fbe81769ca0f998a7e7', 'metadata': {u'groups': u'["local_01", "dpc"]', u'nodepool': u'{"provider_name": "local_01", "node_id": 28227, "image_name": "dpc"}'}, 'human_id': u'd-p-c-local_01-28227'})})
2016-04-14 11:02:38,715 INFO nodepool.NodePool: Deleted jenkins node id: 28227
2016-04-14 11:02:43,520 INFO nodepool.NodePool: Deleted node id: 28227
2016-04-14 11:02:44,563 INFO nodepool.NodePool: Need to launch 1 d-p-c nodes for jenkins1 on local_01
2016-04-14 11:02:44,596 INFO nodepool.NodeLauncher: Creating server with hostname d-p-c-local_01-28228 in local_01 from image dpc for node id: 28228
2016-04-14 11:06:35,854 ERROR nodepool.NodeLauncher: OpenStackCloudException launching node id: 28228 in provider: local_01 error:
Traceback (most recent call last):
  File "/usr/local/lib/python2.7/dist-packages/nodepool/nodepool.py", line 408, in _run
    dt = self.launchNode(session)
  File "/usr/local/lib/python2.7/dist-packages/nodepool/nodepool.py", line 485, in launchNode
    server = self.manager.waitForServer(server, self.launch_timeout)
  File "/usr/local/lib/python2.7/dist-packages/nodepool/provider_manager.py", line 222, in waitForServer
    timeout=timeout)
  File "/usr/local/lib/python2.7/dist-packages/shade/openstackcloud.py", line 3712, in wait_for_server
    wait=True, timeout=remaining_timeout)
  File "/usr/local/lib/python2.7/dist-packages/shade/openstackcloud.py", line 3726, in get_active_server
    extra_data=dict(server=server))
OpenStackCloudException: ('Error in creating the server: No valid host was found. There are not enough hosts available.', {'server': Munch({'OS-EXT-STS:task_state': None, 'addresses': {}, 'image': {u'id': u'5568a9bc-9d2b-4f02-a4d9-2ec8be2ec77a'}, 'networks': {}, 'OS-EXT-STS:vm_state': u'error', 'OS-EXT-SRV-ATTR:instance_name': u'instance-0000043d', 'OS-SRV-USG:launched_at': None, 'NAME_ATTR': 'name', 'flavor': {u'id': u'4'}, 'id': u'fb6bbebf-c598-4eae-ae95-0ed062e694a1', 'cloud': 'defaults', 'user_id': u'2c2a671ce4bd49898cd696a0e8283054', 'OS-DCF:diskConfig': u'MANUAL', 'HUMAN_ID': True, 'accessIPv4': '', 'accessIPv6': '', 'public_v4': '', 'OS-EXT-STS:power_state': 0, 'OS-EXT-AZ:availability_zone': u'', 'config_drive': u'', 'status': u'ERROR', 'updated': u'2016-04-14T03:06:36Z', 'hostId': u'', 'OS-EXT-SRV-ATTR:host': None, 'OS-SRV-USG:terminated_at': None, 'key_name': None, 'public_v6': '', 'request_ids': [], 'private_v4': '', 'OS-EXT-SRV-ATTR:hypervisor_hostname': None, 'name': u'd-p-c-local_01-28228', 'created': u'2016-04-14T03:02:46Z', 'fault': {u'message': u'No valid host was found. There are not enough hosts available.', u'code': 500, u'details': u'  File "/usr/lib/python2.7/dist-packages/nova/conductor/manager.py", line 739, in build_instances\n    request_spec, filter_properties)\n  File "/usr/lib/python2.7/dist-packages/nova/scheduler/utils.py", line 343, in wrapped\n    return func(*args, **kwargs)\n  File "/usr/lib/python2.7/dist-packages/nova/scheduler/client/__init__.py", line 52, in select_destinations\n    context, request_spec, filter_properties)\n  File "/usr/lib/python2.7/dist-packages/nova/scheduler/client/__init__.py", line 37, in __run_method\n    return getattr(self.instance, __name)(*args, **kwargs)\n  File "/usr/lib/python2.7/dist-packages/nova/scheduler/client/query.py", line 34, in select_destinations\n    context, request_spec, filter_properties)\n  File "/usr/lib/python2.7/dist-packages/nova/scheduler/rpcapi.py", line 120, in select_destinations\n    request_spec=request_spec, filter_properties=filter_properties)\n  File "/usr/lib/python2.7/dist-packages/oslo_messaging/rpc/client.py", line 158, in call\n    retry=self.retry)\n  File "/usr/lib/python2.7/dist-packages/oslo_messaging/transport.py", line 90, in _send\n    timeout=timeout, retry=retry)\n  File "/usr/lib/python2.7/dist-packages/oslo_messaging/_drivers/amqpdriver.py", line 533, in send\n    retry=retry)\n  File "/usr/lib/python2.7/dist-packages/oslo_messaging/_drivers/amqpdriver.py", line 524, in _send\n    raise result\n', u'created': u'2016-04-14T03:06:36Z'}, 'region': '', 'x_openstack_request_ids': [], 'os-extended-volumes:volumes_attached': [], 'volumes': [], 'tenant_id': u'3bc6c4940bd74fbe81769ca0f998a7e7', 'metadata': {u'groups': u'["local_01", "dpc"]', u'nodepool': u'{"provider_name": "local_01", "node_id": 28228, "image_name": "dpc"}'}, 'human_id': u'd-p-c-local_01-28228'})}) (Extra: {'server': Munch({'OS-EXT-STS:task_state': None, 'addresses': {}, 'image': {u'id': u'5568a9bc-9d2b-4f02-a4d9-2ec8be2ec77a'}, 'networks': {}, 'OS-EXT-STS:vm_state': u'error', 'OS-EXT-SRV-ATTR:instance_name': u'instance-0000043d', 'OS-SRV-USG:launched_at': None, 'NAME_ATTR': 'name', 'flavor': {u'id': u'4'}, 'id': u'fb6bbebf-c598-4eae-ae95-0ed062e694a1', 'cloud': 'defaults', 'user_id': u'2c2a671ce4bd49898cd696a0e8283054', 'OS-DCF:diskConfig': u'MANUAL', 'HUMAN_ID': True, 'accessIPv4': '', 'accessIPv6': '', 'public_v4': '', 'OS-EXT-STS:power_state': 0, 'OS-EXT-AZ:availability_zone': u'', 'config_drive': u'', 'status': u'ERROR', 'updated': u'2016-04-14T03:06:36Z', 'hostId': u'', 'OS-EXT-SRV-ATTR:host': None, 'OS-SRV-USG:terminated_at': None, 'key_name': None, 'public_v6': '', 'request_ids': [], 'private_v4': '', 'OS-EXT-SRV-ATTR:hypervisor_hostname': None, 'name': u'd-p-c-local_01-28228', 'created': u'2016-04-14T03:02:46Z', 'fault': {u'message': u'No valid host was found. There are not enough hosts available.', u'code': 500, u'details': u'  File "/usr/lib/python2.7/dist-packages/nova/conductor/manager.py", line 739, in build_instances\n    request_spec, filter_properties)\n  File "/usr/lib/python2.7/dist-packages/nova/scheduler/utils.py", line 343, in wrapped\n    return func(*args, **kwargs)\n  File "/usr/lib/python2.7/dist-packages/nova/scheduler/client/__init__.py", line 52, in select_destinations\n    context, request_spec, filter_properties)\n  File "/usr/lib/python2.7/dist-packages/nova/scheduler/client/__init__.py", line 37, in __run_method\n    return getattr(self.instance, __name)(*args, **kwargs)\n  File "/usr/lib/python2.7/dist-packages/nova/scheduler/client/query.py", line 34, in select_destinations\n    context, request_spec, filter_properties)\n  File "/usr/lib/python2.7/dist-packages/nova/scheduler/rpcapi.py", line 120, in select_destinations\n    request_spec=request_spec, filter_properties=filter_properties)\n  File "/usr/lib/python2.7/dist-packages/oslo_messaging/rpc/client.py", line 158, in call\n    retry=self.retry)\n  File "/usr/lib/python2.7/dist-packages/oslo_messaging/transport.py", line 90, in _send\n    timeout=timeout, retry=retry)\n  File "/usr/lib/python2.7/dist-packages/oslo_messaging/_drivers/amqpdriver.py", line 533, in send\n    retry=retry)\n  File "/usr/lib/python2.7/dist-packages/oslo_messaging/_drivers/amqpdriver.py", line 524, in _send\n    raise result\n', u'created': u'2016-04-14T03:06:36Z'}, 'region': '', 'x_openstack_request_ids': [], 'os-extended-volumes:volumes_attached': [], 'volumes': [], 'tenant_id': u'3bc6c4940bd74fbe81769ca0f998a7e7', 'metadata': {u'groups': u'["local_01", "dpc"]', u'nodepool': u'{"provider_name": "local_01", "node_id": 28228, "image_name": "dpc"}'}, 'human_id': u'd-p-c-local_01-28228'})})
2016-04-14 11:06:35,890 INFO nodepool.NodePool: Deleted jenkins node id: 28228
2016-04-14 11:06:40,834 INFO nodepool.NodePool: Deleted node id: 28228
2016-04-14 11:06:45,761 INFO nodepool.NodePool: Need to launch 1 d-p-c nodes for jenkins1 on local_01
2016-04-14 11:06:45,803 INFO nodepool.NodeLauncher: Creating server with hostname d-p-c-local_01-28229 in local_01 from image dpc for node id: 28229
2016-04-14 11:10:36,062 ERROR nodepool.NodeLauncher: OpenStackCloudException launching node id: 28229 in provider: local_01 error:
Traceback (most recent call last):
  File "/usr/local/lib/python2.7/dist-packages/nodepool/nodepool.py", line 408, in _run
    dt = self.launchNode(session)
  File "/usr/local/lib/python2.7/dist-packages/nodepool/nodepool.py", line 485, in launchNode
    server = self.manager.waitForServer(server, self.launch_timeout)
  File "/usr/local/lib/python2.7/dist-packages/nodepool/provider_manager.py", line 222, in waitForServer
    timeout=timeout)
  File "/usr/local/lib/python2.7/dist-packages/shade/openstackcloud.py", line 3712, in wait_for_server
    wait=True, timeout=remaining_timeout)
  File "/usr/local/lib/python2.7/dist-packages/shade/openstackcloud.py", line 3729, in get_active_server
    "Error in creating the server", extra_data=dict(server=server))
OpenStackCloudException: ('Error in creating the server', {'server': Munch({'OS-EXT-STS:task_state': None, 'addresses': {}, 'image': {u'id': u'5568a9bc-9d2b-4f02-a4d9-2ec8be2ec77a'}, 'networks': {}, 'OS-EXT-STS:vm_state': u'error', 'OS-EXT-SRV-ATTR:instance_name': u'instance-00000440', 'OS-SRV-USG:launched_at': None, 'NAME_ATTR': 'name', 'flavor': {u'id': u'4'}, 'id': u'5f2719de-b5da-44e7-b0e4-6f385e4130bc', 'cloud': 'defaults', 'user_id': u'2c2a671ce4bd49898cd696a0e8283054', 'OS-DCF:diskConfig': u'MANUAL', 'HUMAN_ID': True, 'accessIPv4': '', 'accessIPv6': '', 'public_v4': '', 'OS-EXT-STS:power_state': 0, 'OS-EXT-AZ:availability_zone': u'', 'config_drive': u'', 'status': u'ERROR', 'updated': u'2016-04-14T03:10:36Z', 'hostId': u'', 'OS-EXT-SRV-ATTR:host': None, 'OS-SRV-USG:terminated_at': None, 'key_name': None, 'public_v6': '', 'request_ids': [], 'private_v4': '', 'OS-EXT-SRV-ATTR:hypervisor_hostname': None, 'name': u'd-p-c-local_01-28229', 'created': u'2016-04-14T03:06:47Z', 'tenant_id': u'3bc6c4940bd74fbe81769ca0f998a7e7', 'region': '', 'x_openstack_request_ids': [], 'os-extended-volumes:volumes_attached': [], 'volumes': [], 'metadata': {u'groups': u'["local_01", "dpc"]', u'nodepool': u'{"provider_name": "local_01", "node_id": 28229, "image_name": "dpc"}'}, 'human_id': u'd-p-c-local_01-28229'})}) (Extra: {'server': Munch({'OS-EXT-STS:task_state': None, 'addresses': {}, 'image': {u'id': u'5568a9bc-9d2b-4f02-a4d9-2ec8be2ec77a'}, 'networks': {}, 'OS-EXT-STS:vm_state': u'error', 'OS-EXT-SRV-ATTR:instance_name': u'instance-00000440', 'OS-SRV-USG:launched_at': None, 'NAME_ATTR': 'name', 'flavor': {u'id': u'4'}, 'id': u'5f2719de-b5da-44e7-b0e4-6f385e4130bc', 'cloud': 'defaults', 'user_id': u'2c2a671ce4bd49898cd696a0e8283054', 'OS-DCF:diskConfig': u'MANUAL', 'HUMAN_ID': True, 'accessIPv4': '', 'accessIPv6': '', 'public_v4': '', 'OS-EXT-STS:power_state': 0, 'OS-EXT-AZ:availability_zone': u'', 'config_drive': u'', 'status': u'ERROR', 'updated': u'2016-04-14T03:10:36Z', 'hostId': u'', 'OS-EXT-SRV-ATTR:host': None, 'OS-SRV-USG:terminated_at': None, 'key_name': None, 'public_v6': '', 'request_ids': [], 'private_v4': '', 'OS-EXT-SRV-ATTR:hypervisor_hostname': None, 'name': u'd-p-c-local_01-28229', 'created': u'2016-04-14T03:06:47Z', 'tenant_id': u'3bc6c4940bd74fbe81769ca0f998a7e7', 'region': '', 'x_openstack_request_ids': [], 'os-extended-volumes:volumes_attached': [], 'volumes': [], 'metadata': {u'groups': u'["local_01", "dpc"]', u'nodepool': u'{"provider_name": "local_01", "node_id": 28229, "image_name": "dpc"}'}, 'human_id': u'd-p-c-local_01-28229'})})
2016-04-14 11:10:36,120 INFO nodepool.NodePool: Deleted jenkins node id: 28229
2016-04-14 11:10:36,973 INFO nodepool.NodePool: Need to launch 1 d-p-c nodes for jenkins1 on local_01
2016-04-14 11:10:37,014 INFO nodepool.NodeLauncher: Creating server with hostname d-p-c-local_01-28230 in local_01 from image dpc for node id: 28230
2016-04-14 11:10:44,795 INFO nodepool.NodePool: Deleted node id: 28229
2016-04-14 11:14:32,276 ERROR nodepool.NodeLauncher: OpenStackCloudException launching node id: 28230 in provider: local_01 error:
Traceback (most recent call last):
  File "/usr/local/lib/python2.7/dist-packages/nodepool/nodepool.py", line 408, in _run
    dt = self.launchNode(session)
  File "/usr/local/lib/python2.7/dist-packages/nodepool/nodepool.py", line 485, in launchNode
    server = self.manager.waitForServer(server, self.launch_timeout)
  File "/usr/local/lib/python2.7/dist-packages/nodepool/provider_manager.py", line 222, in waitForServer
    timeout=timeout)
  File "/usr/local/lib/python2.7/dist-packages/shade/openstackcloud.py", line 3712, in wait_for_server
    wait=True, timeout=remaining_timeout)
  File "/usr/local/lib/python2.7/dist-packages/shade/openstackcloud.py", line 3726, in get_active_server
    extra_data=dict(server=server))
OpenStackCloudException: ('Error in creating the server: No valid host was found. There are not enough hosts available.', {'server': Munch({'OS-EXT-STS:task_state': None, 'addresses': {}, 'image': {u'id': u'5568a9bc-9d2b-4f02-a4d9-2ec8be2ec77a'}, 'networks': {}, 'OS-EXT-STS:vm_state': u'error', 'OS-EXT-SRV-ATTR:instance_name': u'instance-00000443', 'OS-SRV-USG:launched_at': None, 'NAME_ATTR': 'name', 'flavor': {u'id': u'4'}, 'id': u'15e8521a-9078-4b65-a828-344aecb5b198', 'cloud': 'defaults', 'user_id': u'2c2a671ce4bd49898cd696a0e8283054', 'OS-DCF:diskConfig': u'MANUAL', 'HUMAN_ID': True, 'accessIPv4': '', 'accessIPv6': '', 'public_v4': '', 'OS-EXT-STS:power_state': 0, 'OS-EXT-AZ:availability_zone': u'', 'config_drive': u'', 'status': u'ERROR', 'updated': u'2016-04-14T03:14:32Z', 'hostId': u'', 'OS-EXT-SRV-ATTR:host': None, 'OS-SRV-USG:terminated_at': None, 'key_name': None, 'public_v6': '', 'request_ids': [], 'private_v4': '', 'OS-EXT-SRV-ATTR:hypervisor_hostname': None, 'name': u'd-p-c-local_01-28230', 'created': u'2016-04-14T03:10:39Z', 'fault': {u'message': u'No valid host was found. There are not enough hosts available.', u'code': 500, u'details': u'  File "/usr/lib/python2.7/dist-packages/nova/conductor/manager.py", line 739, in build_instances\n    request_spec, filter_properties)\n  File "/usr/lib/python2.7/dist-packages/nova/scheduler/utils.py", line 343, in wrapped\n    return func(*args, **kwargs)\n  File "/usr/lib/python2.7/dist-packages/nova/scheduler/client/__init__.py", line 52, in select_destinations\n    context, request_spec, filter_properties)\n  File "/usr/lib/python2.7/dist-packages/nova/scheduler/client/__init__.py", line 37, in __run_method\n    return getattr(self.instance, __name)(*args, **kwargs)\n  File "/usr/lib/python2.7/dist-packages/nova/scheduler/client/query.py", line 34, in select_destinations\n    context, request_spec, filter_properties)\n  File "/usr/lib/python2.7/dist-packages/nova/scheduler/rpcapi.py", line 120, in select_destinations\n    request_spec=request_spec, filter_properties=filter_properties)\n  File "/usr/lib/python2.7/dist-packages/oslo_messaging/rpc/client.py", line 158, in call\n    retry=self.retry)\n  File "/usr/lib/python2.7/dist-packages/oslo_messaging/transport.py", line 90, in _send\n    timeout=timeout, retry=retry)\n  File "/usr/lib/python2.7/dist-packages/oslo_messaging/_drivers/amqpdriver.py", line 533, in send\n    retry=retry)\n  File "/usr/lib/python2.7/dist-packages/oslo_messaging/_drivers/amqpdriver.py", line 524, in _send\n    raise result\n', u'created': u'2016-04-14T03:14:32Z'}, 'region': '', 'x_openstack_request_ids': [], 'os-extended-volumes:volumes_attached': [], 'volumes': [], 'tenant_id': u'3bc6c4940bd74fbe81769ca0f998a7e7', 'metadata': {u'groups': u'["local_01", "dpc"]', u'nodepool': u'{"provider_name": "local_01", "node_id": 28230, "image_name": "dpc"}'}, 'human_id': u'd-p-c-local_01-28230'})}) (Extra: {'server': Munch({'OS-EXT-STS:task_state': None, 'addresses': {}, 'image': {u'id': u'5568a9bc-9d2b-4f02-a4d9-2ec8be2ec77a'}, 'networks': {}, 'OS-EXT-STS:vm_state': u'error', 'OS-EXT-SRV-ATTR:instance_name': u'instance-00000443', 'OS-SRV-USG:launched_at': None, 'NAME_ATTR': 'name', 'flavor': {u'id': u'4'}, 'id': u'15e8521a-9078-4b65-a828-344aecb5b198', 'cloud': 'defaults', 'user_id': u'2c2a671ce4bd49898cd696a0e8283054', 'OS-DCF:diskConfig': u'MANUAL', 'HUMAN_ID': True, 'accessIPv4': '', 'accessIPv6': '', 'public_v4': '', 'OS-EXT-STS:power_state': 0, 'OS-EXT-AZ:availability_zone': u'', 'config_drive': u'', 'status': u'ERROR', 'updated': u'2016-04-14T03:14:32Z', 'hostId': u'', 'OS-EXT-SRV-ATTR:host': None, 'OS-SRV-USG:terminated_at': None, 'key_name': None, 'public_v6': '', 'request_ids': [], 'private_v4': '', 'OS-EXT-SRV-ATTR:hypervisor_hostname': None, 'name': u'd-p-c-local_01-28230', 'created': u'2016-04-14T03:10:39Z', 'fault': {u'message': u'No valid host was found. There are not enough hosts available.', u'code': 500, u'details': u'  File "/usr/lib/python2.7/dist-packages/nova/conductor/manager.py", line 739, in build_instances\n    request_spec, filter_properties)\n  File "/usr/lib/python2.7/dist-packages/nova/scheduler/utils.py", line 343, in wrapped\n    return func(*args, **kwargs)\n  File "/usr/lib/python2.7/dist-packages/nova/scheduler/client/__init__.py", line 52, in select_destinations\n    context, request_spec, filter_properties)\n  File "/usr/lib/python2.7/dist-packages/nova/scheduler/client/__init__.py", line 37, in __run_method\n    return getattr(self.instance, __name)(*args, **kwargs)\n  File "/usr/lib/python2.7/dist-packages/nova/scheduler/client/query.py", line 34, in select_destinations\n    context, request_spec, filter_properties)\n  File "/usr/lib/python2.7/dist-packages/nova/scheduler/rpcapi.py", line 120, in select_destinations\n    request_spec=request_spec, filter_properties=filter_properties)\n  File "/usr/lib/python2.7/dist-packages/oslo_messaging/rpc/client.py", line 158, in call\n    retry=self.retry)\n  File "/usr/lib/python2.7/dist-packages/oslo_messaging/transport.py", line 90, in _send\n    timeout=timeout, retry=retry)\n  File "/usr/lib/python2.7/dist-packages/oslo_messaging/_drivers/amqpdriver.py", line 533, in send\n    retry=retry)\n  File "/usr/lib/python2.7/dist-packages/oslo_messaging/_drivers/amqpdriver.py", line 524, in _send\n    raise result\n', u'created': u'2016-04-14T03:14:32Z'}, 'region': '', 'x_openstack_request_ids': [], 'os-extended-volumes:volumes_attached': [], 'volumes': [], 'tenant_id': u'3bc6c4940bd74fbe81769ca0f998a7e7', 'metadata': {u'groups': u'["local_01", "dpc"]', u'nodepool': u'{"provider_name": "local_01", "node_id": 28230, "image_name": "dpc"}'}, 'human_id': u'd-p-c-local_01-28230'})})
2016-04-14 11:14:32,321 INFO nodepool.NodePool: Deleted jenkins node id: 28230
2016-04-14 11:14:37,039 INFO nodepool.NodePool: Deleted node id: 28230
2016-04-14 11:14:38,257 INFO nodepool.NodePool: Need to launch 1 d-p-c nodes for jenkins1 on local_01
2016-04-14 11:14:38,288 INFO nodepool.NodeLauncher: Creating server with hostname d-p-c-local_01-28231 in local_01 from image dpc for node id: 28231
2016-04-14 11:18:30,375 ERROR nodepool.NodeLauncher: OpenStackCloudException launching node id: 28231 in provider: local_01 error:
Traceback (most recent call last):
  File "/usr/local/lib/python2.7/dist-packages/nodepool/nodepool.py", line 408, in _run
    dt = self.launchNode(session)
  File "/usr/local/lib/python2.7/dist-packages/nodepool/nodepool.py", line 485, in launchNode
    server = self.manager.waitForServer(server, self.launch_timeout)
  File "/usr/local/lib/python2.7/dist-packages/nodepool/provider_manager.py", line 222, in waitForServer
    timeout=timeout)
  File "/usr/local/lib/python2.7/dist-packages/shade/openstackcloud.py", line 3712, in wait_for_server
    wait=True, timeout=remaining_timeout)
  File "/usr/local/lib/python2.7/dist-packages/shade/openstackcloud.py", line 3726, in get_active_server
    extra_data=dict(server=server))
OpenStackCloudException: ('Error in creating the server: No valid host was found. There are not enough hosts available.', {'server': Munch({'OS-EXT-STS:task_state': None, 'addresses': {}, 'image': {u'id': u'5568a9bc-9d2b-4f02-a4d9-2ec8be2ec77a'}, 'networks': {}, 'OS-EXT-STS:vm_state': u'error', 'OS-EXT-SRV-ATTR:instance_name': u'instance-00000446', 'OS-SRV-USG:launched_at': None, 'NAME_ATTR': 'name', 'flavor': {u'id': u'4'}, 'id': u'46d2471e-c59f-4ffe-8629-85e1dbc80b0b', 'cloud': 'defaults', 'user_id': u'2c2a671ce4bd49898cd696a0e8283054', 'OS-DCF:diskConfig': u'MANUAL', 'HUMAN_ID': True, 'accessIPv4': '', 'accessIPv6': '', 'public_v4': '', 'OS-EXT-STS:power_state': 0, 'OS-EXT-AZ:availability_zone': u'', 'config_drive': u'', 'status': u'ERROR', 'updated': u'2016-04-14T03:18:30Z', 'hostId': u'', 'OS-EXT-SRV-ATTR:host': None, 'OS-SRV-USG:terminated_at': None, 'key_name': None, 'public_v6': '', 'request_ids': [], 'private_v4': '', 'OS-EXT-SRV-ATTR:hypervisor_hostname': None, 'name': u'd-p-c-local_01-28231', 'created': u'2016-04-14T03:14:40Z', 'fault': {u'message': u'No valid host was found. There are not enough hosts available.', u'code': 500, u'details': u'  File "/usr/lib/python2.7/dist-packages/nova/conductor/manager.py", line 739, in build_instances\n    request_spec, filter_properties)\n  File "/usr/lib/python2.7/dist-packages/nova/scheduler/utils.py", line 343, in wrapped\n    return func(*args, **kwargs)\n  File "/usr/lib/python2.7/dist-packages/nova/scheduler/client/__init__.py", line 52, in select_destinations\n    context, request_spec, filter_properties)\n  File "/usr/lib/python2.7/dist-packages/nova/scheduler/client/__init__.py", line 37, in __run_method\n    return getattr(self.instance, __name)(*args, **kwargs)\n  File "/usr/lib/python2.7/dist-packages/nova/scheduler/client/query.py", line 34, in select_destinations\n    context, request_spec, filter_properties)\n  File "/usr/lib/python2.7/dist-packages/nova/scheduler/rpcapi.py", line 120, in select_destinations\n    request_spec=request_spec, filter_properties=filter_properties)\n  File "/usr/lib/python2.7/dist-packages/oslo_messaging/rpc/client.py", line 158, in call\n    retry=self.retry)\n  File "/usr/lib/python2.7/dist-packages/oslo_messaging/transport.py", line 90, in _send\n    timeout=timeout, retry=retry)\n  File "/usr/lib/python2.7/dist-packages/oslo_messaging/_drivers/amqpdriver.py", line 533, in send\n    retry=retry)\n  File "/usr/lib/python2.7/dist-packages/oslo_messaging/_drivers/amqpdriver.py", line 524, in _send\n    raise result\n', u'created': u'2016-04-14T03:18:30Z'}, 'region': '', 'x_openstack_request_ids': [], 'os-extended-volumes:volumes_attached': [], 'volumes': [], 'tenant_id': u'3bc6c4940bd74fbe81769ca0f998a7e7', 'metadata': {u'groups': u'["local_01", "dpc"]', u'nodepool': u'{"provider_name": "local_01", "node_id": 28231, "image_name": "dpc"}'}, 'human_id': u'd-p-c-local_01-28231'})}) (Extra: {'server': Munch({'OS-EXT-STS:task_state': None, 'addresses': {}, 'image': {u'id': u'5568a9bc-9d2b-4f02-a4d9-2ec8be2ec77a'}, 'networks': {}, 'OS-EXT-STS:vm_state': u'error', 'OS-EXT-SRV-ATTR:instance_name': u'instance-00000446', 'OS-SRV-USG:launched_at': None, 'NAME_ATTR': 'name', 'flavor': {u'id': u'4'}, 'id': u'46d2471e-c59f-4ffe-8629-85e1dbc80b0b', 'cloud': 'defaults', 'user_id': u'2c2a671ce4bd49898cd696a0e8283054', 'OS-DCF:diskConfig': u'MANUAL', 'HUMAN_ID': True, 'accessIPv4': '', 'accessIPv6': '', 'public_v4': '', 'OS-EXT-STS:power_state': 0, 'OS-EXT-AZ:availability_zone': u'', 'config_drive': u'', 'status': u'ERROR', 'updated': u'2016-04-14T03:18:30Z', 'hostId': u'', 'OS-EXT-SRV-ATTR:host': None, 'OS-SRV-USG:terminated_at': None, 'key_name': None, 'public_v6': '', 'request_ids': [], 'private_v4': '', 'OS-EXT-SRV-ATTR:hypervisor_hostname': None, 'name': u'd-p-c-local_01-28231', 'created': u'2016-04-14T03:14:40Z', 'fault': {u'message': u'No valid host was found. There are not enough hosts available.', u'code': 500, u'details': u'  File "/usr/lib/python2.7/dist-packages/nova/conductor/manager.py", line 739, in build_instances\n    request_spec, filter_properties)\n  File "/usr/lib/python2.7/dist-packages/nova/scheduler/utils.py", line 343, in wrapped\n    return func(*args, **kwargs)\n  File "/usr/lib/python2.7/dist-packages/nova/scheduler/client/__init__.py", line 52, in select_destinations\n    context, request_spec, filter_properties)\n  File "/usr/lib/python2.7/dist-packages/nova/scheduler/client/__init__.py", line 37, in __run_method\n    return getattr(self.instance, __name)(*args, **kwargs)\n  File "/usr/lib/python2.7/dist-packages/nova/scheduler/client/query.py", line 34, in select_destinations\n    context, request_spec, filter_properties)\n  File "/usr/lib/python2.7/dist-packages/nova/scheduler/rpcapi.py", line 120, in select_destinations\n    request_spec=request_spec, filter_properties=filter_properties)\n  File "/usr/lib/python2.7/dist-packages/oslo_messaging/rpc/client.py", line 158, in call\n    retry=self.retry)\n  File "/usr/lib/python2.7/dist-packages/oslo_messaging/transport.py", line 90, in _send\n    timeout=timeout, retry=retry)\n  File "/usr/lib/python2.7/dist-packages/oslo_messaging/_drivers/amqpdriver.py", line 533, in send\n    retry=retry)\n  File "/usr/lib/python2.7/dist-packages/oslo_messaging/_drivers/amqpdriver.py", line 524, in _send\n    raise result\n', u'created': u'2016-04-14T03:18:30Z'}, 'region': '', 'x_openstack_request_ids': [], 'os-extended-volumes:volumes_attached': [], 'volumes': [], 'tenant_id': u'3bc6c4940bd74fbe81769ca0f998a7e7', 'metadata': {u'groups': u'["local_01", "dpc"]', u'nodepool': u'{"provider_name": "local_01", "node_id": 28231, "image_name": "dpc"}'}, 'human_id': u'd-p-c-local_01-28231'})})
2016-04-14 11:18:30,419 INFO nodepool.NodePool: Deleted jenkins node id: 28231
2016-04-14 11:18:35,218 INFO nodepool.NodePool: Deleted node id: 28231
2016-04-14 11:18:39,401 INFO nodepool.NodePool: Need to launch 1 d-p-c nodes for jenkins1 on local_01
2016-04-14 11:18:39,439 INFO nodepool.NodeLauncher: Creating server with hostname d-p-c-local_01-28232 in local_01 from image dpc for node id: 28232
2016-04-14 11:22:31,491 ERROR nodepool.NodeLauncher: OpenStackCloudException launching node id: 28232 in provider: local_01 error:
Traceback (most recent call last):
  File "/usr/local/lib/python2.7/dist-packages/nodepool/nodepool.py", line 408, in _run
    dt = self.launchNode(session)
  File "/usr/local/lib/python2.7/dist-packages/nodepool/nodepool.py", line 485, in launchNode
    server = self.manager.waitForServer(server, self.launch_timeout)
  File "/usr/local/lib/python2.7/dist-packages/nodepool/provider_manager.py", line 222, in waitForServer
    timeout=timeout)
  File "/usr/local/lib/python2.7/dist-packages/shade/openstackcloud.py", line 3712, in wait_for_server
    wait=True, timeout=remaining_timeout)
  File "/usr/local/lib/python2.7/dist-packages/shade/openstackcloud.py", line 3726, in get_active_server
    extra_data=dict(server=server))
OpenStackCloudException: ('Error in creating the server: No valid host was found. There are not enough hosts available.', {'server': Munch({'OS-EXT-STS:task_state': None, 'addresses': {}, 'image': {u'id': u'5568a9bc-9d2b-4f02-a4d9-2ec8be2ec77a'}, 'networks': {}, 'OS-EXT-STS:vm_state': u'error', 'OS-EXT-SRV-ATTR:instance_name': u'instance-00000449', 'OS-SRV-USG:launched_at': None, 'NAME_ATTR': 'name', 'flavor': {u'id': u'4'}, 'id': u'2aa222a2-07a5-40df-a4ec-7312416e675f', 'cloud': 'defaults', 'user_id': u'2c2a671ce4bd49898cd696a0e8283054', 'OS-DCF:diskConfig': u'MANUAL', 'HUMAN_ID': True, 'accessIPv4': '', 'accessIPv6': '', 'public_v4': '', 'OS-EXT-STS:power_state': 0, 'OS-EXT-AZ:availability_zone': u'', 'config_drive': u'', 'status': u'ERROR', 'updated': u'2016-04-14T03:22:32Z', 'hostId': u'', 'OS-EXT-SRV-ATTR:host': None, 'OS-SRV-USG:terminated_at': None, 'key_name': None, 'public_v6': '', 'request_ids': [], 'private_v4': '', 'OS-EXT-SRV-ATTR:hypervisor_hostname': None, 'name': u'd-p-c-local_01-28232', 'created': u'2016-04-14T03:18:41Z', 'fault': {u'message': u'No valid host was found. There are not enough hosts available.', u'code': 500, u'details': u'  File "/usr/lib/python2.7/dist-packages/nova/conductor/manager.py", line 739, in build_instances\n    request_spec, filter_properties)\n  File "/usr/lib/python2.7/dist-packages/nova/scheduler/utils.py", line 343, in wrapped\n    return func(*args, **kwargs)\n  File "/usr/lib/python2.7/dist-packages/nova/scheduler/client/__init__.py", line 52, in select_destinations\n    context, request_spec, filter_properties)\n  File "/usr/lib/python2.7/dist-packages/nova/scheduler/client/__init__.py", line 37, in __run_method\n    return getattr(self.instance, __name)(*args, **kwargs)\n  File "/usr/lib/python2.7/dist-packages/nova/scheduler/client/query.py", line 34, in select_destinations\n    context, request_spec, filter_properties)\n  File "/usr/lib/python2.7/dist-packages/nova/scheduler/rpcapi.py", line 120, in select_destinations\n    request_spec=request_spec, filter_properties=filter_properties)\n  File "/usr/lib/python2.7/dist-packages/oslo_messaging/rpc/client.py", line 158, in call\n    retry=self.retry)\n  File "/usr/lib/python2.7/dist-packages/oslo_messaging/transport.py", line 90, in _send\n    timeout=timeout, retry=retry)\n  File "/usr/lib/python2.7/dist-packages/oslo_messaging/_drivers/amqpdriver.py", line 533, in send\n    retry=retry)\n  File "/usr/lib/python2.7/dist-packages/oslo_messaging/_drivers/amqpdriver.py", line 524, in _send\n    raise result\n', u'created': u'2016-04-14T03:22:32Z'}, 'region': '', 'x_openstack_request_ids': [], 'os-extended-volumes:volumes_attached': [], 'volumes': [], 'tenant_id': u'3bc6c4940bd74fbe81769ca0f998a7e7', 'metadata': {u'groups': u'["local_01", "dpc"]', u'nodepool': u'{"provider_name": "local_01", "node_id": 28232, "image_name": "dpc"}'}, 'human_id': u'd-p-c-local_01-28232'})}) (Extra: {'server': Munch({'OS-EXT-STS:task_state': None, 'addresses': {}, 'image': {u'id': u'5568a9bc-9d2b-4f02-a4d9-2ec8be2ec77a'}, 'networks': {}, 'OS-EXT-STS:vm_state': u'error', 'OS-EXT-SRV-ATTR:instance_name': u'instance-00000449', 'OS-SRV-USG:launched_at': None, 'NAME_ATTR': 'name', 'flavor': {u'id': u'4'}, 'id': u'2aa222a2-07a5-40df-a4ec-7312416e675f', 'cloud': 'defaults', 'user_id': u'2c2a671ce4bd49898cd696a0e8283054', 'OS-DCF:diskConfig': u'MANUAL', 'HUMAN_ID': True, 'accessIPv4': '', 'accessIPv6': '', 'public_v4': '', 'OS-EXT-STS:power_state': 0, 'OS-EXT-AZ:availability_zone': u'', 'config_drive': u'', 'status': u'ERROR', 'updated': u'2016-04-14T03:22:32Z', 'hostId': u'', 'OS-EXT-SRV-ATTR:host': None, 'OS-SRV-USG:terminated_at': None, 'key_name': None, 'public_v6': '', 'request_ids': [], 'private_v4': '', 'OS-EXT-SRV-ATTR:hypervisor_hostname': None, 'name': u'd-p-c-local_01-28232', 'created': u'2016-04-14T03:18:41Z', 'fault': {u'message': u'No valid host was found. There are not enough hosts available.', u'code': 500, u'details': u'  File "/usr/lib/python2.7/dist-packages/nova/conductor/manager.py", line 739, in build_instances\n    request_spec, filter_properties)\n  File "/usr/lib/python2.7/dist-packages/nova/scheduler/utils.py", line 343, in wrapped\n    return func(*args, **kwargs)\n  File "/usr/lib/python2.7/dist-packages/nova/scheduler/client/__init__.py", line 52, in select_destinations\n    context, request_spec, filter_properties)\n  File "/usr/lib/python2.7/dist-packages/nova/scheduler/client/__init__.py", line 37, in __run_method\n    return getattr(self.instance, __name)(*args, **kwargs)\n  File "/usr/lib/python2.7/dist-packages/nova/scheduler/client/query.py", line 34, in select_destinations\n    context, request_spec, filter_properties)\n  File "/usr/lib/python2.7/dist-packages/nova/scheduler/rpcapi.py", line 120, in select_destinations\n    request_spec=request_spec, filter_properties=filter_properties)\n  File "/usr/lib/python2.7/dist-packages/oslo_messaging/rpc/client.py", line 158, in call\n    retry=self.retry)\n  File "/usr/lib/python2.7/dist-packages/oslo_messaging/transport.py", line 90, in _send\n    timeout=timeout, retry=retry)\n  File "/usr/lib/python2.7/dist-packages/oslo_messaging/_drivers/amqpdriver.py", line 533, in send\n    retry=retry)\n  File "/usr/lib/python2.7/dist-packages/oslo_messaging/_drivers/amqpdriver.py", line 524, in _send\n    raise result\n', u'created': u'2016-04-14T03:22:32Z'}, 'region': '', 'x_openstack_request_ids': [], 'os-extended-volumes:volumes_attached': [], 'volumes': [], 'tenant_id': u'3bc6c4940bd74fbe81769ca0f998a7e7', 'metadata': {u'groups': u'["local_01", "dpc"]', u'nodepool': u'{"provider_name": "local_01", "node_id": 28232, "image_name": "dpc"}'}, 'human_id': u'd-p-c-local_01-28232'})})
2016-04-14 11:22:31,555 INFO nodepool.NodePool: Deleted jenkins node id: 28232
2016-04-14 11:22:36,368 INFO nodepool.NodePool: Deleted node id: 28232
2016-04-14 11:22:40,581 INFO nodepool.NodePool: Need to launch 1 d-p-c nodes for jenkins1 on local_01
2016-04-14 11:22:40,625 INFO nodepool.NodeLauncher: Creating server with hostname d-p-c-local_01-28233 in local_01 from image dpc for node id: 28233
2016-04-14 11:26:34,932 ERROR nodepool.NodeLauncher: OpenStackCloudException launching node id: 28233 in provider: local_01 error:
Traceback (most recent call last):
  File "/usr/local/lib/python2.7/dist-packages/nodepool/nodepool.py", line 408, in _run
    dt = self.launchNode(session)
  File "/usr/local/lib/python2.7/dist-packages/nodepool/nodepool.py", line 485, in launchNode
    server = self.manager.waitForServer(server, self.launch_timeout)
  File "/usr/local/lib/python2.7/dist-packages/nodepool/provider_manager.py", line 222, in waitForServer
    timeout=timeout)
  File "/usr/local/lib/python2.7/dist-packages/shade/openstackcloud.py", line 3712, in wait_for_server
    wait=True, timeout=remaining_timeout)
  File "/usr/local/lib/python2.7/dist-packages/shade/openstackcloud.py", line 3726, in get_active_server
    extra_data=dict(server=server))
OpenStackCloudException: ('Error in creating the server: No valid host was found. There are not enough hosts available.', {'server': Munch({'OS-EXT-STS:task_state': None, 'addresses': {}, 'image': {u'id': u'5568a9bc-9d2b-4f02-a4d9-2ec8be2ec77a'}, 'networks': {}, 'OS-EXT-STS:vm_state': u'error', 'OS-EXT-SRV-ATTR:instance_name': u'instance-0000044c', 'OS-SRV-USG:launched_at': None, 'NAME_ATTR': 'name', 'flavor': {u'id': u'4'}, 'id': u'45ef09ae-9899-4a35-9755-fd9d6b126f4a', 'cloud': 'defaults', 'user_id': u'2c2a671ce4bd49898cd696a0e8283054', 'OS-DCF:diskConfig': u'MANUAL', 'HUMAN_ID': True, 'accessIPv4': '', 'accessIPv6': '', 'public_v4': '', 'OS-EXT-STS:power_state': 0, 'OS-EXT-AZ:availability_zone': u'', 'config_drive': u'', 'status': u'ERROR', 'updated': u'2016-04-14T03:26:35Z', 'hostId': u'', 'OS-EXT-SRV-ATTR:host': None, 'OS-SRV-USG:terminated_at': None, 'key_name': None, 'public_v6': '', 'request_ids': [], 'private_v4': '', 'OS-EXT-SRV-ATTR:hypervisor_hostname': None, 'name': u'd-p-c-local_01-28233', 'created': u'2016-04-14T03:22:42Z', 'fault': {u'message': u'No valid host was found. There are not enough hosts available.', u'code': 500, u'details': u'  File "/usr/lib/python2.7/dist-packages/nova/conductor/manager.py", line 739, in build_instances\n    request_spec, filter_properties)\n  File "/usr/lib/python2.7/dist-packages/nova/scheduler/utils.py", line 343, in wrapped\n    return func(*args, **kwargs)\n  File "/usr/lib/python2.7/dist-packages/nova/scheduler/client/__init__.py", line 52, in select_destinations\n    context, request_spec, filter_properties)\n  File "/usr/lib/python2.7/dist-packages/nova/scheduler/client/__init__.py", line 37, in __run_method\n    return getattr(self.instance, __name)(*args, **kwargs)\n  File "/usr/lib/python2.7/dist-packages/nova/scheduler/client/query.py", line 34, in select_destinations\n    context, request_spec, filter_properties)\n  File "/usr/lib/python2.7/dist-packages/nova/scheduler/rpcapi.py", line 120, in select_destinations\n    request_spec=request_spec, filter_properties=filter_properties)\n  File "/usr/lib/python2.7/dist-packages/oslo_messaging/rpc/client.py", line 158, in call\n    retry=self.retry)\n  File "/usr/lib/python2.7/dist-packages/oslo_messaging/transport.py", line 90, in _send\n    timeout=timeout, retry=retry)\n  File "/usr/lib/python2.7/dist-packages/oslo_messaging/_drivers/amqpdriver.py", line 533, in send\n    retry=retry)\n  File "/usr/lib/python2.7/dist-packages/oslo_messaging/_drivers/amqpdriver.py", line 524, in _send\n    raise result\n', u'created': u'2016-04-14T03:26:35Z'}, 'region': '', 'x_openstack_request_ids': [], 'os-extended-volumes:volumes_attached': [], 'volumes': [], 'tenant_id': u'3bc6c4940bd74fbe81769ca0f998a7e7', 'metadata': {u'groups': u'["local_01", "dpc"]', u'nodepool': u'{"provider_name": "local_01", "node_id": 28233, "image_name": "dpc"}'}, 'human_id': u'd-p-c-local_01-28233'})}) (Extra: {'server': Munch({'OS-EXT-STS:task_state': None, 'addresses': {}, 'image': {u'id': u'5568a9bc-9d2b-4f02-a4d9-2ec8be2ec77a'}, 'networks': {}, 'OS-EXT-STS:vm_state': u'error', 'OS-EXT-SRV-ATTR:instance_name': u'instance-0000044c', 'OS-SRV-USG:launched_at': None, 'NAME_ATTR': 'name', 'flavor': {u'id': u'4'}, 'id': u'45ef09ae-9899-4a35-9755-fd9d6b126f4a', 'cloud': 'defaults', 'user_id': u'2c2a671ce4bd49898cd696a0e8283054', 'OS-DCF:diskConfig': u'MANUAL', 'HUMAN_ID': True, 'accessIPv4': '', 'accessIPv6': '', 'public_v4': '', 'OS-EXT-STS:power_state': 0, 'OS-EXT-AZ:availability_zone': u'', 'config_drive': u'', 'status': u'ERROR', 'updated': u'2016-04-14T03:26:35Z', 'hostId': u'', 'OS-EXT-SRV-ATTR:host': None, 'OS-SRV-USG:terminated_at': None, 'key_name': None, 'public_v6': '', 'request_ids': [], 'private_v4': '', 'OS-EXT-SRV-ATTR:hypervisor_hostname': None, 'name': u'd-p-c-local_01-28233', 'created': u'2016-04-14T03:22:42Z', 'fault': {u'message': u'No valid host was found. There are not enough hosts available.', u'code': 500, u'details': u'  File "/usr/lib/python2.7/dist-packages/nova/conductor/manager.py", line 739, in build_instances\n    request_spec, filter_properties)\n  File "/usr/lib/python2.7/dist-packages/nova/scheduler/utils.py", line 343, in wrapped\n    return func(*args, **kwargs)\n  File "/usr/lib/python2.7/dist-packages/nova/scheduler/client/__init__.py", line 52, in select_destinations\n    context, request_spec, filter_properties)\n  File "/usr/lib/python2.7/dist-packages/nova/scheduler/client/__init__.py", line 37, in __run_method\n    return getattr(self.instance, __name)(*args, **kwargs)\n  File "/usr/lib/python2.7/dist-packages/nova/scheduler/client/query.py", line 34, in select_destinations\n    context, request_spec, filter_properties)\n  File "/usr/lib/python2.7/dist-packages/nova/scheduler/rpcapi.py", line 120, in select_destinations\n    request_spec=request_spec, filter_properties=filter_properties)\n  File "/usr/lib/python2.7/dist-packages/oslo_messaging/rpc/client.py", line 158, in call\n    retry=self.retry)\n  File "/usr/lib/python2.7/dist-packages/oslo_messaging/transport.py", line 90, in _send\n    timeout=timeout, retry=retry)\n  File "/usr/lib/python2.7/dist-packages/oslo_messaging/_drivers/amqpdriver.py", line 533, in send\n    retry=retry)\n  File "/usr/lib/python2.7/dist-packages/oslo_messaging/_drivers/amqpdriver.py", line 524, in _send\n    raise result\n', u'created': u'2016-04-14T03:26:35Z'}, 'region': '', 'x_openstack_request_ids': [], 'os-extended-volumes:volumes_attached': [], 'volumes': [], 'tenant_id': u'3bc6c4940bd74fbe81769ca0f998a7e7', 'metadata': {u'groups': u'["local_01", "dpc"]', u'nodepool': u'{"provider_name": "local_01", "node_id": 28233, "image_name": "dpc"}'}, 'human_id': u'd-p-c-local_01-28233'})})
2016-04-14 11:26:34,976 INFO nodepool.NodePool: Deleted jenkins node id: 28233
2016-04-14 11:26:39,798 INFO nodepool.NodePool: Deleted node id: 28233
2016-04-14 11:26:41,758 INFO nodepool.NodePool: Need to launch 1 d-p-c nodes for jenkins1 on local_01
2016-04-14 11:26:41,802 INFO nodepool.NodeLauncher: Creating server with hostname d-p-c-local_01-28234 in local_01 from image dpc for node id: 28234
2016-04-14 11:30:34,441 ERROR nodepool.NodeLauncher: OpenStackCloudException launching node id: 28234 in provider: local_01 error:
Traceback (most recent call last):
  File "/usr/local/lib/python2.7/dist-packages/nodepool/nodepool.py", line 408, in _run
    dt = self.launchNode(session)
  File "/usr/local/lib/python2.7/dist-packages/nodepool/nodepool.py", line 485, in launchNode
    server = self.manager.waitForServer(server, self.launch_timeout)
  File "/usr/local/lib/python2.7/dist-packages/nodepool/provider_manager.py", line 222, in waitForServer
    timeout=timeout)
  File "/usr/local/lib/python2.7/dist-packages/shade/openstackcloud.py", line 3712, in wait_for_server
    wait=True, timeout=remaining_timeout)
  File "/usr/local/lib/python2.7/dist-packages/shade/openstackcloud.py", line 3726, in get_active_server
    extra_data=dict(server=server))
OpenStackCloudException: ('Error in creating the server: No valid host was found. There are not enough hosts available.', {'server': Munch({'OS-EXT-STS:task_state': None, 'addresses': {}, 'image': {u'id': u'5568a9bc-9d2b-4f02-a4d9-2ec8be2ec77a'}, 'networks': {}, 'OS-EXT-STS:vm_state': u'error', 'OS-EXT-SRV-ATTR:instance_name': u'instance-0000044f', 'OS-SRV-USG:launched_at': None, 'NAME_ATTR': 'name', 'flavor': {u'id': u'4'}, 'id': u'24787353-84ee-4304-b7d4-d8f223521e29', 'cloud': 'defaults', 'user_id': u'2c2a671ce4bd49898cd696a0e8283054', 'OS-DCF:diskConfig': u'MANUAL', 'HUMAN_ID': True, 'accessIPv4': '', 'accessIPv6': '', 'public_v4': '', 'OS-EXT-STS:power_state': 0, 'OS-EXT-AZ:availability_zone': u'', 'config_drive': u'', 'status': u'ERROR', 'updated': u'2016-04-14T03:30:34Z', 'hostId': u'', 'OS-EXT-SRV-ATTR:host': None, 'OS-SRV-USG:terminated_at': None, 'key_name': None, 'public_v6': '', 'request_ids': [], 'private_v4': '', 'OS-EXT-SRV-ATTR:hypervisor_hostname': None, 'name': u'd-p-c-local_01-28234', 'created': u'2016-04-14T03:26:43Z', 'fault': {u'message': u'No valid host was found. There are not enough hosts available.', u'code': 500, u'details': u'  File "/usr/lib/python2.7/dist-packages/nova/conductor/manager.py", line 739, in build_instances\n    request_spec, filter_properties)\n  File "/usr/lib/python2.7/dist-packages/nova/scheduler/utils.py", line 343, in wrapped\n    return func(*args, **kwargs)\n  File "/usr/lib/python2.7/dist-packages/nova/scheduler/client/__init__.py", line 52, in select_destinations\n    context, request_spec, filter_properties)\n  File "/usr/lib/python2.7/dist-packages/nova/scheduler/client/__init__.py", line 37, in __run_method\n    return getattr(self.instance, __name)(*args, **kwargs)\n  File "/usr/lib/python2.7/dist-packages/nova/scheduler/client/query.py", line 34, in select_destinations\n    context, request_spec, filter_properties)\n  File "/usr/lib/python2.7/dist-packages/nova/scheduler/rpcapi.py", line 120, in select_destinations\n    request_spec=request_spec, filter_properties=filter_properties)\n  File "/usr/lib/python2.7/dist-packages/oslo_messaging/rpc/client.py", line 158, in call\n    retry=self.retry)\n  File "/usr/lib/python2.7/dist-packages/oslo_messaging/transport.py", line 90, in _send\n    timeout=timeout, retry=retry)\n  File "/usr/lib/python2.7/dist-packages/oslo_messaging/_drivers/amqpdriver.py", line 533, in send\n    retry=retry)\n  File "/usr/lib/python2.7/dist-packages/oslo_messaging/_drivers/amqpdriver.py", line 524, in _send\n    raise result\n', u'created': u'2016-04-14T03:30:34Z'}, 'region': '', 'x_openstack_request_ids': [], 'os-extended-volumes:volumes_attached': [], 'volumes': [], 'tenant_id': u'3bc6c4940bd74fbe81769ca0f998a7e7', 'metadata': {u'groups': u'["local_01", "dpc"]', u'nodepool': u'{"provider_name": "local_01", "node_id": 28234, "image_name": "dpc"}'}, 'human_id': u'd-p-c-local_01-28234'})}) (Extra: {'server': Munch({'OS-EXT-STS:task_state': None, 'addresses': {}, 'image': {u'id': u'5568a9bc-9d2b-4f02-a4d9-2ec8be2ec77a'}, 'networks': {}, 'OS-EXT-STS:vm_state': u'error', 'OS-EXT-SRV-ATTR:instance_name': u'instance-0000044f', 'OS-SRV-USG:launched_at': None, 'NAME_ATTR': 'name', 'flavor': {u'id': u'4'}, 'id': u'24787353-84ee-4304-b7d4-d8f223521e29', 'cloud': 'defaults', 'user_id': u'2c2a671ce4bd49898cd696a0e8283054', 'OS-DCF:diskConfig': u'MANUAL', 'HUMAN_ID': True, 'accessIPv4': '', 'accessIPv6': '', 'public_v4': '', 'OS-EXT-STS:power_state': 0, 'OS-EXT-AZ:availability_zone': u'', 'config_drive': u'', 'status': u'ERROR', 'updated': u'2016-04-14T03:30:34Z', 'hostId': u'', 'OS-EXT-SRV-ATTR:host': None, 'OS-SRV-USG:terminated_at': None, 'key_name': None, 'public_v6': '', 'request_ids': [], 'private_v4': '', 'OS-EXT-SRV-ATTR:hypervisor_hostname': None, 'name': u'd-p-c-local_01-28234', 'created': u'2016-04-14T03:26:43Z', 'fault': {u'message': u'No valid host was found. There are not enough hosts available.', u'code': 500, u'details': u'  File "/usr/lib/python2.7/dist-packages/nova/conductor/manager.py", line 739, in build_instances\n    request_spec, filter_properties)\n  File "/usr/lib/python2.7/dist-packages/nova/scheduler/utils.py", line 343, in wrapped\n    return func(*args, **kwargs)\n  File "/usr/lib/python2.7/dist-packages/nova/scheduler/client/__init__.py", line 52, in select_destinations\n    context, request_spec, filter_properties)\n  File "/usr/lib/python2.7/dist-packages/nova/scheduler/client/__init__.py", line 37, in __run_method\n    return getattr(self.instance, __name)(*args, **kwargs)\n  File "/usr/lib/python2.7/dist-packages/nova/scheduler/client/query.py", line 34, in select_destinations\n    context, request_spec, filter_properties)\n  File "/usr/lib/python2.7/dist-packages/nova/scheduler/rpcapi.py", line 120, in select_destinations\n    request_spec=request_spec, filter_properties=filter_properties)\n  File "/usr/lib/python2.7/dist-packages/oslo_messaging/rpc/client.py", line 158, in call\n    retry=self.retry)\n  File "/usr/lib/python2.7/dist-packages/oslo_messaging/transport.py", line 90, in _send\n    timeout=timeout, retry=retry)\n  File "/usr/lib/python2.7/dist-packages/oslo_messaging/_drivers/amqpdriver.py", line 533, in send\n    retry=retry)\n  File "/usr/lib/python2.7/dist-packages/oslo_messaging/_drivers/amqpdriver.py", line 524, in _send\n    raise result\n', u'created': u'2016-04-14T03:30:34Z'}, 'region': '', 'x_openstack_request_ids': [], 'os-extended-volumes:volumes_attached': [], 'volumes': [], 'tenant_id': u'3bc6c4940bd74fbe81769ca0f998a7e7', 'metadata': {u'groups': u'["local_01", "dpc"]', u'nodepool': u'{"provider_name": "local_01", "node_id": 28234, "image_name": "dpc"}'}, 'human_id': u'd-p-c-local_01-28234'})})
2016-04-14 11:30:34,492 INFO nodepool.NodePool: Deleted jenkins node id: 28234
2016-04-14 11:30:39,202 INFO nodepool.NodePool: Deleted node id: 28234
2016-04-14 11:30:42,984 INFO nodepool.NodePool: Need to launch 1 d-p-c nodes for jenkins1 on local_01
2016-04-14 11:30:43,024 INFO nodepool.NodeLauncher: Creating server with hostname d-p-c-local_01-28235 in local_01 from image dpc for node id: 28235
2016-04-14 11:34:41,305 ERROR nodepool.NodeLauncher: OpenStackCloudException launching node id: 28235 in provider: local_01 error:
Traceback (most recent call last):
  File "/usr/local/lib/python2.7/dist-packages/nodepool/nodepool.py", line 408, in _run
    dt = self.launchNode(session)
  File "/usr/local/lib/python2.7/dist-packages/nodepool/nodepool.py", line 485, in launchNode
    server = self.manager.waitForServer(server, self.launch_timeout)
  File "/usr/local/lib/python2.7/dist-packages/nodepool/provider_manager.py", line 222, in waitForServer
    timeout=timeout)
  File "/usr/local/lib/python2.7/dist-packages/shade/openstackcloud.py", line 3712, in wait_for_server
    wait=True, timeout=remaining_timeout)
  File "/usr/local/lib/python2.7/dist-packages/shade/openstackcloud.py", line 3726, in get_active_server
    extra_data=dict(server=server))
OpenStackCloudException: ('Error in creating the server: No valid host was found. There are not enough hosts available.', {'server': Munch({'OS-EXT-STS:task_state': None, 'addresses': {}, 'image': {u'id': u'5568a9bc-9d2b-4f02-a4d9-2ec8be2ec77a'}, 'networks': {}, 'OS-EXT-STS:vm_state': u'error', 'OS-EXT-SRV-ATTR:instance_name': u'instance-00000452', 'OS-SRV-USG:launched_at': None, 'NAME_ATTR': 'name', 'flavor': {u'id': u'4'}, 'id': u'd46aeca7-ddec-40aa-aa1c-77477a8285a1', 'cloud': 'defaults', 'user_id': u'2c2a671ce4bd49898cd696a0e8283054', 'OS-DCF:diskConfig': u'MANUAL', 'HUMAN_ID': True, 'accessIPv4': '', 'accessIPv6': '', 'public_v4': '', 'OS-EXT-STS:power_state': 0, 'OS-EXT-AZ:availability_zone': u'', 'config_drive': u'', 'status': u'ERROR', 'updated': u'2016-04-14T03:34:41Z', 'hostId': u'', 'OS-EXT-SRV-ATTR:host': None, 'OS-SRV-USG:terminated_at': None, 'key_name': None, 'public_v6': '', 'request_ids': [], 'private_v4': '', 'OS-EXT-SRV-ATTR:hypervisor_hostname': None, 'name': u'd-p-c-local_01-28235', 'created': u'2016-04-14T03:30:44Z', 'fault': {u'message': u'No valid host was found. There are not enough hosts available.', u'code': 500, u'details': u'  File "/usr/lib/python2.7/dist-packages/nova/conductor/manager.py", line 739, in build_instances\n    request_spec, filter_properties)\n  File "/usr/lib/python2.7/dist-packages/nova/scheduler/utils.py", line 343, in wrapped\n    return func(*args, **kwargs)\n  File "/usr/lib/python2.7/dist-packages/nova/scheduler/client/__init__.py", line 52, in select_destinations\n    context, request_spec, filter_properties)\n  File "/usr/lib/python2.7/dist-packages/nova/scheduler/client/__init__.py", line 37, in __run_method\n    return getattr(self.instance, __name)(*args, **kwargs)\n  File "/usr/lib/python2.7/dist-packages/nova/scheduler/client/query.py", line 34, in select_destinations\n    context, request_spec, filter_properties)\n  File "/usr/lib/python2.7/dist-packages/nova/scheduler/rpcapi.py", line 120, in select_destinations\n    request_spec=request_spec, filter_properties=filter_properties)\n  File "/usr/lib/python2.7/dist-packages/oslo_messaging/rpc/client.py", line 158, in call\n    retry=self.retry)\n  File "/usr/lib/python2.7/dist-packages/oslo_messaging/transport.py", line 90, in _send\n    timeout=timeout, retry=retry)\n  File "/usr/lib/python2.7/dist-packages/oslo_messaging/_drivers/amqpdriver.py", line 533, in send\n    retry=retry)\n  File "/usr/lib/python2.7/dist-packages/oslo_messaging/_drivers/amqpdriver.py", line 524, in _send\n    raise result\n', u'created': u'2016-04-14T03:34:41Z'}, 'region': '', 'x_openstack_request_ids': [], 'os-extended-volumes:volumes_attached': [], 'volumes': [], 'tenant_id': u'3bc6c4940bd74fbe81769ca0f998a7e7', 'metadata': {u'groups': u'["local_01", "dpc"]', u'nodepool': u'{"provider_name": "local_01", "node_id": 28235, "image_name": "dpc"}'}, 'human_id': u'd-p-c-local_01-28235'})}) (Extra: {'server': Munch({'OS-EXT-STS:task_state': None, 'addresses': {}, 'image': {u'id': u'5568a9bc-9d2b-4f02-a4d9-2ec8be2ec77a'}, 'networks': {}, 'OS-EXT-STS:vm_state': u'error', 'OS-EXT-SRV-ATTR:instance_name': u'instance-00000452', 'OS-SRV-USG:launched_at': None, 'NAME_ATTR': 'name', 'flavor': {u'id': u'4'}, 'id': u'd46aeca7-ddec-40aa-aa1c-77477a8285a1', 'cloud': 'defaults', 'user_id': u'2c2a671ce4bd49898cd696a0e8283054', 'OS-DCF:diskConfig': u'MANUAL', 'HUMAN_ID': True, 'accessIPv4': '', 'accessIPv6': '', 'public_v4': '', 'OS-EXT-STS:power_state': 0, 'OS-EXT-AZ:availability_zone': u'', 'config_drive': u'', 'status': u'ERROR', 'updated': u'2016-04-14T03:34:41Z', 'hostId': u'', 'OS-EXT-SRV-ATTR:host': None, 'OS-SRV-USG:terminated_at': None, 'key_name': None, 'public_v6': '', 'request_ids': [], 'private_v4': '', 'OS-EXT-SRV-ATTR:hypervisor_hostname': None, 'name': u'd-p-c-local_01-28235', 'created': u'2016-04-14T03:30:44Z', 'fault': {u'message': u'No valid host was found. There are not enough hosts available.', u'code': 500, u'details': u'  File "/usr/lib/python2.7/dist-packages/nova/conductor/manager.py", line 739, in build_instances\n    request_spec, filter_properties)\n  File "/usr/lib/python2.7/dist-packages/nova/scheduler/utils.py", line 343, in wrapped\n    return func(*args, **kwargs)\n  File "/usr/lib/python2.7/dist-packages/nova/scheduler/client/__init__.py", line 52, in select_destinations\n    context, request_spec, filter_properties)\n  File "/usr/lib/python2.7/dist-packages/nova/scheduler/client/__init__.py", line 37, in __run_method\n    return getattr(self.instance, __name)(*args, **kwargs)\n  File "/usr/lib/python2.7/dist-packages/nova/scheduler/client/query.py", line 34, in select_destinations\n    context, request_spec, filter_properties)\n  File "/usr/lib/python2.7/dist-packages/nova/scheduler/rpcapi.py", line 120, in select_destinations\n    request_spec=request_spec, filter_properties=filter_properties)\n  File "/usr/lib/python2.7/dist-packages/oslo_messaging/rpc/client.py", line 158, in call\n    retry=self.retry)\n  File "/usr/lib/python2.7/dist-packages/oslo_messaging/transport.py", line 90, in _send\n    timeout=timeout, retry=retry)\n  File "/usr/lib/python2.7/dist-packages/oslo_messaging/_drivers/amqpdriver.py", line 533, in send\n    retry=retry)\n  File "/usr/lib/python2.7/dist-packages/oslo_messaging/_drivers/amqpdriver.py", line 524, in _send\n    raise result\n', u'created': u'2016-04-14T03:34:41Z'}, 'region': '', 'x_openstack_request_ids': [], 'os-extended-volumes:volumes_attached': [], 'volumes': [], 'tenant_id': u'3bc6c4940bd74fbe81769ca0f998a7e7', 'metadata': {u'groups': u'["local_01", "dpc"]', u'nodepool': u'{"provider_name": "local_01", "node_id": 28235, "image_name": "dpc"}'}, 'human_id': u'd-p-c-local_01-28235'})})
2016-04-14 11:34:41,356 INFO nodepool.NodePool: Deleted jenkins node id: 28235
2016-04-14 11:34:44,168 INFO nodepool.NodePool: Need to launch 1 d-p-c nodes for jenkins1 on local_01
2016-04-14 11:34:44,202 INFO nodepool.NodeLauncher: Creating server with hostname d-p-c-local_01-28236 in local_01 from image dpc for node id: 28236
2016-04-14 11:34:48,365 INFO nodepool.NodePool: Deleted node id: 28235
2016-04-14 11:38:39,366 ERROR nodepool.NodeLauncher: OpenStackCloudException launching node id: 28236 in provider: local_01 error:
Traceback (most recent call last):
  File "/usr/local/lib/python2.7/dist-packages/nodepool/nodepool.py", line 408, in _run
    dt = self.launchNode(session)
  File "/usr/local/lib/python2.7/dist-packages/nodepool/nodepool.py", line 485, in launchNode
    server = self.manager.waitForServer(server, self.launch_timeout)
  File "/usr/local/lib/python2.7/dist-packages/nodepool/provider_manager.py", line 222, in waitForServer
    timeout=timeout)
  File "/usr/local/lib/python2.7/dist-packages/shade/openstackcloud.py", line 3712, in wait_for_server
    wait=True, timeout=remaining_timeout)
  File "/usr/local/lib/python2.7/dist-packages/shade/openstackcloud.py", line 3726, in get_active_server
    extra_data=dict(server=server))
OpenStackCloudException: ('Error in creating the server: No valid host was found. There are not enough hosts available.', {'server': Munch({'OS-EXT-STS:task_state': None, 'addresses': {}, 'image': {u'id': u'5568a9bc-9d2b-4f02-a4d9-2ec8be2ec77a'}, 'networks': {}, 'OS-EXT-STS:vm_state': u'error', 'OS-EXT-SRV-ATTR:instance_name': u'instance-00000455', 'OS-SRV-USG:launched_at': None, 'NAME_ATTR': 'name', 'flavor': {u'id': u'4'}, 'id': u'f3749b67-565c-4836-a44e-d0e1b8524b18', 'cloud': 'defaults', 'user_id': u'2c2a671ce4bd49898cd696a0e8283054', 'OS-DCF:diskConfig': u'MANUAL', 'HUMAN_ID': True, 'accessIPv4': '', 'accessIPv6': '', 'public_v4': '', 'OS-EXT-STS:power_state': 0, 'OS-EXT-AZ:availability_zone': u'', 'config_drive': u'', 'status': u'ERROR', 'updated': u'2016-04-14T03:38:40Z', 'hostId': u'', 'OS-EXT-SRV-ATTR:host': None, 'OS-SRV-USG:terminated_at': None, 'key_name': None, 'public_v6': '', 'request_ids': [], 'private_v4': '', 'OS-EXT-SRV-ATTR:hypervisor_hostname': None, 'name': u'd-p-c-local_01-28236', 'created': u'2016-04-14T03:34:48Z', 'fault': {u'message': u'No valid host was found. There are not enough hosts available.', u'code': 500, u'details': u'  File "/usr/lib/python2.7/dist-packages/nova/conductor/manager.py", line 739, in build_instances\n    request_spec, filter_properties)\n  File "/usr/lib/python2.7/dist-packages/nova/scheduler/utils.py", line 343, in wrapped\n    return func(*args, **kwargs)\n  File "/usr/lib/python2.7/dist-packages/nova/scheduler/client/__init__.py", line 52, in select_destinations\n    context, request_spec, filter_properties)\n  File "/usr/lib/python2.7/dist-packages/nova/scheduler/client/__init__.py", line 37, in __run_method\n    return getattr(self.instance, __name)(*args, **kwargs)\n  File "/usr/lib/python2.7/dist-packages/nova/scheduler/client/query.py", line 34, in select_destinations\n    context, request_spec, filter_properties)\n  File "/usr/lib/python2.7/dist-packages/nova/scheduler/rpcapi.py", line 120, in select_destinations\n    request_spec=request_spec, filter_properties=filter_properties)\n  File "/usr/lib/python2.7/dist-packages/oslo_messaging/rpc/client.py", line 158, in call\n    retry=self.retry)\n  File "/usr/lib/python2.7/dist-packages/oslo_messaging/transport.py", line 90, in _send\n    timeout=timeout, retry=retry)\n  File "/usr/lib/python2.7/dist-packages/oslo_messaging/_drivers/amqpdriver.py", line 533, in send\n    retry=retry)\n  File "/usr/lib/python2.7/dist-packages/oslo_messaging/_drivers/amqpdriver.py", line 524, in _send\n    raise result\n', u'created': u'2016-04-14T03:38:40Z'}, 'region': '', 'x_openstack_request_ids': [], 'os-extended-volumes:volumes_attached': [], 'volumes': [], 'tenant_id': u'3bc6c4940bd74fbe81769ca0f998a7e7', 'metadata': {u'groups': u'["local_01", "dpc"]', u'nodepool': u'{"provider_name": "local_01", "node_id": 28236, "image_name": "dpc"}'}, 'human_id': u'd-p-c-local_01-28236'})}) (Extra: {'server': Munch({'OS-EXT-STS:task_state': None, 'addresses': {}, 'image': {u'id': u'5568a9bc-9d2b-4f02-a4d9-2ec8be2ec77a'}, 'networks': {}, 'OS-EXT-STS:vm_state': u'error', 'OS-EXT-SRV-ATTR:instance_name': u'instance-00000455', 'OS-SRV-USG:launched_at': None, 'NAME_ATTR': 'name', 'flavor': {u'id': u'4'}, 'id': u'f3749b67-565c-4836-a44e-d0e1b8524b18', 'cloud': 'defaults', 'user_id': u'2c2a671ce4bd49898cd696a0e8283054', 'OS-DCF:diskConfig': u'MANUAL', 'HUMAN_ID': True, 'accessIPv4': '', 'accessIPv6': '', 'public_v4': '', 'OS-EXT-STS:power_state': 0, 'OS-EXT-AZ:availability_zone': u'', 'config_drive': u'', 'status': u'ERROR', 'updated': u'2016-04-14T03:38:40Z', 'hostId': u'', 'OS-EXT-SRV-ATTR:host': None, 'OS-SRV-USG:terminated_at': None, 'key_name': None, 'public_v6': '', 'request_ids': [], 'private_v4': '', 'OS-EXT-SRV-ATTR:hypervisor_hostname': None, 'name': u'd-p-c-local_01-28236', 'created': u'2016-04-14T03:34:48Z', 'fault': {u'message': u'No valid host was found. There are not enough hosts available.', u'code': 500, u'details': u'  File "/usr/lib/python2.7/dist-packages/nova/conductor/manager.py", line 739, in build_instances\n    request_spec, filter_properties)\n  File "/usr/lib/python2.7/dist-packages/nova/scheduler/utils.py", line 343, in wrapped\n    return func(*args, **kwargs)\n  File "/usr/lib/python2.7/dist-packages/nova/scheduler/client/__init__.py", line 52, in select_destinations\n    context, request_spec, filter_properties)\n  File "/usr/lib/python2.7/dist-packages/nova/scheduler/client/__init__.py", line 37, in __run_method\n    return getattr(self.instance, __name)(*args, **kwargs)\n  File "/usr/lib/python2.7/dist-packages/nova/scheduler/client/query.py", line 34, in select_destinations\n    context, request_spec, filter_properties)\n  File "/usr/lib/python2.7/dist-packages/nova/scheduler/rpcapi.py", line 120, in select_destinations\n    request_spec=request_spec, filter_properties=filter_properties)\n  File "/usr/lib/python2.7/dist-packages/oslo_messaging/rpc/client.py", line 158, in call\n    retry=self.retry)\n  File "/usr/lib/python2.7/dist-packages/oslo_messaging/transport.py", line 90, in _send\n    timeout=timeout, retry=retry)\n  File "/usr/lib/python2.7/dist-packages/oslo_messaging/_drivers/amqpdriver.py", line 533, in send\n    retry=retry)\n  File "/usr/lib/python2.7/dist-packages/oslo_messaging/_drivers/amqpdriver.py", line 524, in _send\n    raise result\n', u'created': u'2016-04-14T03:38:40Z'}, 'region': '', 'x_openstack_request_ids': [], 'os-extended-volumes:volumes_attached': [], 'volumes': [], 'tenant_id': u'3bc6c4940bd74fbe81769ca0f998a7e7', 'metadata': {u'groups': u'["local_01", "dpc"]', u'nodepool': u'{"provider_name": "local_01", "node_id": 28236, "image_name": "dpc"}'}, 'human_id': u'd-p-c-local_01-28236'})})
2016-04-14 11:38:39,404 INFO nodepool.NodePool: Deleted jenkins node id: 28236
2016-04-14 11:38:44,085 INFO nodepool.NodePool: Deleted node id: 28236
2016-04-14 11:38:45,336 INFO nodepool.NodePool: Need to launch 1 d-p-c nodes for jenkins1 on local_01
2016-04-14 11:38:45,370 INFO nodepool.NodeLauncher: Creating server with hostname d-p-c-local_01-28237 in local_01 from image dpc for node id: 28237
2016-04-14 11:49:45,133 INFO nodepool.NodePool: Setting building node id: 28237 to delete on startup
2016-04-14 11:49:45,204 INFO nodepool.NodePool: Need to launch 1 d-p-c nodes for jenkins1 on local_01
2016-04-14 11:49:45,241 INFO nodepool.NodeLauncher: Creating server with hostname d-p-c-local_01-28238 in local_01 from image dpc for node id: 28238
2016-04-14 11:50:00,026 INFO nodepool.NodePool: Deleted jenkins node id: 28237
2016-04-14 11:50:09,651 INFO nodepool.NodePool: Deleted node id: 28237
2016-04-14 11:53:56,011 ERROR nodepool.utils: Exception while testing ssh access:
Traceback (most recent call last):
  File "/usr/local/lib/python2.7/dist-packages/nodepool/nodeutils.py", line 55, in ssh_connect
    client = SSHClient(ip, username, **connect_kwargs)
  File "/usr/local/lib/python2.7/dist-packages/nodepool/sshclient.py", line 30, in __init__
    key_filename=key_filename)
  File "/usr/local/lib/python2.7/dist-packages/paramiko/client.py", line 292, in connect
    retry_on_signal(lambda: sock.connect(addr))
  File "/usr/local/lib/python2.7/dist-packages/paramiko/util.py", line 270, in retry_on_signal
    return function()
  File "/usr/local/lib/python2.7/dist-packages/paramiko/client.py", line 292, in <lambda>
    retry_on_signal(lambda: sock.connect(addr))
  File "/usr/lib/python2.7/socket.py", line 224, in meth
    return getattr(self._sock,name)(*args)
error: [Errno 110] Connection timed out
2016-04-14 11:53:58,015 ERROR nodepool.NodeLauncher: Timeout launching node id: 28238 in provider: local_01 error: Timeout waiting for ssh access
2016-04-14 11:53:58,089 INFO nodepool.NodePool: Deleted jenkins node id: 28238
2016-04-14 11:54:06,571 INFO nodepool.NodePool: Need to launch 1 d-p-c nodes for jenkins1 on local_01
2016-04-14 11:54:06,615 INFO nodepool.NodeLauncher: Creating server with hostname d-p-c-local_01-28239 in local_01 from image dpc for node id: 28239
2016-04-14 11:54:08,718 INFO nodepool.NodePool: Deleted node id: 28238
2016-04-14 11:58:06,630 ERROR nodepool.utils: Exception while testing ssh access:
Traceback (most recent call last):
  File "/usr/local/lib/python2.7/dist-packages/nodepool/nodeutils.py", line 55, in ssh_connect
    client = SSHClient(ip, username, **connect_kwargs)
  File "/usr/local/lib/python2.7/dist-packages/nodepool/sshclient.py", line 30, in __init__
    key_filename=key_filename)
  File "/usr/local/lib/python2.7/dist-packages/paramiko/client.py", line 292, in connect
    retry_on_signal(lambda: sock.connect(addr))
  File "/usr/local/lib/python2.7/dist-packages/paramiko/util.py", line 270, in retry_on_signal
    return function()
  File "/usr/local/lib/python2.7/dist-packages/paramiko/client.py", line 292, in <lambda>
    retry_on_signal(lambda: sock.connect(addr))
  File "/usr/lib/python2.7/socket.py", line 224, in meth
    return getattr(self._sock,name)(*args)
error: [Errno 110] Connection timed out
2016-04-14 11:58:08,635 ERROR nodepool.NodeLauncher: Timeout launching node id: 28239 in provider: local_01 error: Timeout waiting for ssh access
2016-04-14 11:58:08,694 INFO nodepool.NodePool: Deleted jenkins node id: 28239
2016-04-14 11:58:17,564 INFO nodepool.NodePool: Deleted node id: 28239
2016-04-14 11:58:17,864 INFO nodepool.NodePool: Need to launch 1 d-p-c nodes for jenkins1 on local_01
2016-04-14 11:58:17,902 INFO nodepool.NodeLauncher: Creating server with hostname d-p-c-local_01-28240 in local_01 from image dpc for node id: 28240
2016-04-14 12:00:05,979 INFO nodepool.NodePool: Setting building node id: 28240 to delete on startup
2016-04-14 12:00:06,043 INFO nodepool.NodePool: Need to launch 1 d-p-c nodes for jenkins1 on local_01
2016-04-14 12:00:06,084 INFO nodepool.NodeLauncher: Creating server with hostname d-p-c-local_01-28241 in local_01 from image dpc for node id: 28241
2016-04-14 12:01:00,029 INFO nodepool.NodePool: Deleted jenkins node id: 28240
2016-04-14 12:01:46,394 INFO nodepool.NodePool: Deleted node id: 28240
2016-04-14 12:04:19,110 ERROR nodepool.utils: Exception while testing ssh access:
Traceback (most recent call last):
  File "/usr/local/lib/python2.7/dist-packages/nodepool/nodeutils.py", line 55, in ssh_connect
    client = SSHClient(ip, username, **connect_kwargs)
  File "/usr/local/lib/python2.7/dist-packages/nodepool/sshclient.py", line 30, in __init__
    key_filename=key_filename)
  File "/usr/local/lib/python2.7/dist-packages/paramiko/client.py", line 292, in connect
    retry_on_signal(lambda: sock.connect(addr))
  File "/usr/local/lib/python2.7/dist-packages/paramiko/util.py", line 270, in retry_on_signal
    return function()
  File "/usr/local/lib/python2.7/dist-packages/paramiko/client.py", line 292, in <lambda>
    retry_on_signal(lambda: sock.connect(addr))
  File "/usr/lib/python2.7/socket.py", line 224, in meth
    return getattr(self._sock,name)(*args)
error: [Errno 110] Connection timed out
2016-04-14 12:04:21,115 ERROR nodepool.NodeLauncher: Timeout launching node id: 28241 in provider: local_01 error: Timeout waiting for ssh access
2016-04-14 12:04:21,178 INFO nodepool.NodePool: Deleted jenkins node id: 28241
2016-04-14 12:04:27,422 INFO nodepool.NodePool: Need to launch 1 d-p-c nodes for jenkins1 on local_01
2016-04-14 12:04:27,460 INFO nodepool.NodeLauncher: Creating server with hostname d-p-c-local_01-28242 in local_01 from image dpc for node id: 28242
2016-04-14 12:04:31,559 INFO nodepool.NodePool: Deleted node id: 28241
2016-04-14 12:08:28,710 ERROR nodepool.utils: Exception while testing ssh access:
Traceback (most recent call last):
  File "/usr/local/lib/python2.7/dist-packages/nodepool/nodeutils.py", line 55, in ssh_connect
    client = SSHClient(ip, username, **connect_kwargs)
  File "/usr/local/lib/python2.7/dist-packages/nodepool/sshclient.py", line 30, in __init__
    key_filename=key_filename)
  File "/usr/local/lib/python2.7/dist-packages/paramiko/client.py", line 292, in connect
    retry_on_signal(lambda: sock.connect(addr))
  File "/usr/local/lib/python2.7/dist-packages/paramiko/util.py", line 270, in retry_on_signal
    return function()
  File "/usr/local/lib/python2.7/dist-packages/paramiko/client.py", line 292, in <lambda>
    retry_on_signal(lambda: sock.connect(addr))
  File "/usr/lib/python2.7/socket.py", line 224, in meth
    return getattr(self._sock,name)(*args)
error: [Errno 110] Connection timed out
2016-04-14 12:08:30,715 ERROR nodepool.NodeLauncher: Timeout launching node id: 28242 in provider: local_01 error: Timeout waiting for ssh access
2016-04-14 12:08:30,775 INFO nodepool.NodePool: Deleted jenkins node id: 28242
2016-04-14 12:08:38,767 INFO nodepool.NodePool: Need to launch 1 d-p-c nodes for jenkins1 on local_01
2016-04-14 12:08:38,800 INFO nodepool.NodeLauncher: Creating server with hostname d-p-c-local_01-28243 in local_01 from image dpc for node id: 28243
2016-04-14 12:08:41,097 INFO nodepool.NodePool: Deleted node id: 28242
2016-04-14 12:12:17,938 INFO nodepool.NodePool: Setting building node id: 28243 to delete on startup
2016-04-14 12:12:18,015 INFO nodepool.NodePool: Need to launch 1 d-p-c nodes for jenkins1 on local_01
2016-04-14 12:12:18,046 INFO nodepool.NodeLauncher: Creating server with hostname d-p-c-local_01-28244 in local_01 from image dpc for node id: 28244
2016-04-14 12:13:00,040 INFO nodepool.NodePool: Deleted jenkins node id: 28243
2016-04-14 12:13:48,436 INFO nodepool.NodePool: Deleted node id: 28243
2016-04-14 12:16:31,782 ERROR nodepool.utils: Exception while testing ssh access:
Traceback (most recent call last):
  File "/usr/local/lib/python2.7/dist-packages/nodepool/nodeutils.py", line 55, in ssh_connect
    client = SSHClient(ip, username, **connect_kwargs)
  File "/usr/local/lib/python2.7/dist-packages/nodepool/sshclient.py", line 30, in __init__
    key_filename=key_filename)
  File "/usr/local/lib/python2.7/dist-packages/paramiko/client.py", line 292, in connect
    retry_on_signal(lambda: sock.connect(addr))
  File "/usr/local/lib/python2.7/dist-packages/paramiko/util.py", line 270, in retry_on_signal
    return function()
  File "/usr/local/lib/python2.7/dist-packages/paramiko/client.py", line 292, in <lambda>
    retry_on_signal(lambda: sock.connect(addr))
  File "/usr/lib/python2.7/socket.py", line 224, in meth
    return getattr(self._sock,name)(*args)
error: [Errno 110] Connection timed out
2016-04-14 12:16:33,788 ERROR nodepool.NodeLauncher: Timeout launching node id: 28244 in provider: local_01 error: Timeout waiting for ssh access
2016-04-14 12:16:33,866 INFO nodepool.NodePool: Deleted jenkins node id: 28244
2016-04-14 12:16:39,474 INFO nodepool.NodePool: Need to launch 1 d-p-c nodes for jenkins1 on local_01
2016-04-14 12:16:39,518 INFO nodepool.NodeLauncher: Creating server with hostname d-p-c-local_01-28245 in local_01 from image dpc for node id: 28245
2016-04-14 12:16:45,440 INFO nodepool.NodePool: Deleted node id: 28244
2016-04-14 12:20:39,846 ERROR nodepool.utils: Exception while testing ssh access:
Traceback (most recent call last):
  File "/usr/local/lib/python2.7/dist-packages/nodepool/nodeutils.py", line 55, in ssh_connect
    client = SSHClient(ip, username, **connect_kwargs)
  File "/usr/local/lib/python2.7/dist-packages/nodepool/sshclient.py", line 30, in __init__
    key_filename=key_filename)
  File "/usr/local/lib/python2.7/dist-packages/paramiko/client.py", line 292, in connect
    retry_on_signal(lambda: sock.connect(addr))
  File "/usr/local/lib/python2.7/dist-packages/paramiko/util.py", line 270, in retry_on_signal
    return function()
  File "/usr/local/lib/python2.7/dist-packages/paramiko/client.py", line 292, in <lambda>
    retry_on_signal(lambda: sock.connect(addr))
  File "/usr/lib/python2.7/socket.py", line 224, in meth
    return getattr(self._sock,name)(*args)
error: [Errno 110] Connection timed out
2016-04-14 12:20:41,853 ERROR nodepool.NodeLauncher: Timeout launching node id: 28245 in provider: local_01 error: Timeout waiting for ssh access
2016-04-14 12:20:41,923 INFO nodepool.NodePool: Deleted jenkins node id: 28245
2016-04-14 12:20:50,560 INFO nodepool.NodePool: Deleted node id: 28245
2016-04-14 12:20:50,802 INFO nodepool.NodePool: Need to launch 1 d-p-c nodes for jenkins1 on local_01
2016-04-14 12:20:50,837 INFO nodepool.NodeLauncher: Creating server with hostname d-p-c-local_01-28246 in local_01 from image dpc for node id: 28246
2016-04-14 12:24:52,134 ERROR nodepool.utils: Exception while testing ssh access:
Traceback (most recent call last):
  File "/usr/local/lib/python2.7/dist-packages/nodepool/nodeutils.py", line 55, in ssh_connect
    client = SSHClient(ip, username, **connect_kwargs)
  File "/usr/local/lib/python2.7/dist-packages/nodepool/sshclient.py", line 30, in __init__
    key_filename=key_filename)
  File "/usr/local/lib/python2.7/dist-packages/paramiko/client.py", line 292, in connect
    retry_on_signal(lambda: sock.connect(addr))
  File "/usr/local/lib/python2.7/dist-packages/paramiko/util.py", line 270, in retry_on_signal
    return function()
  File "/usr/local/lib/python2.7/dist-packages/paramiko/client.py", line 292, in <lambda>
    retry_on_signal(lambda: sock.connect(addr))
  File "/usr/lib/python2.7/socket.py", line 224, in meth
    return getattr(self._sock,name)(*args)
error: [Errno 110] Connection timed out
2016-04-14 12:24:54,139 ERROR nodepool.NodeLauncher: Timeout launching node id: 28246 in provider: local_01 error: Timeout waiting for ssh access
2016-04-14 12:24:54,198 INFO nodepool.NodePool: Deleted jenkins node id: 28246
2016-04-14 12:25:02,131 INFO nodepool.NodePool: Need to launch 1 d-p-c nodes for jenkins1 on local_01
2016-04-14 12:25:02,179 INFO nodepool.NodeLauncher: Creating server with hostname d-p-c-local_01-28247 in local_01 from image dpc for node id: 28247
2016-04-14 12:25:04,130 INFO nodepool.NodePool: Deleted node id: 28246
2016-04-14 12:29:01,607 ERROR nodepool.utils: Exception while testing ssh access:
Traceback (most recent call last):
  File "/usr/local/lib/python2.7/dist-packages/nodepool/nodeutils.py", line 55, in ssh_connect
    client = SSHClient(ip, username, **connect_kwargs)
  File "/usr/local/lib/python2.7/dist-packages/nodepool/sshclient.py", line 30, in __init__
    key_filename=key_filename)
  File "/usr/local/lib/python2.7/dist-packages/paramiko/client.py", line 292, in connect
    retry_on_signal(lambda: sock.connect(addr))
  File "/usr/local/lib/python2.7/dist-packages/paramiko/util.py", line 270, in retry_on_signal
    return function()
  File "/usr/local/lib/python2.7/dist-packages/paramiko/client.py", line 292, in <lambda>
    retry_on_signal(lambda: sock.connect(addr))
  File "/usr/lib/python2.7/socket.py", line 224, in meth
    return getattr(self._sock,name)(*args)
error: [Errno 110] Connection timed out
2016-04-14 12:29:03,613 ERROR nodepool.NodeLauncher: Timeout launching node id: 28247 in provider: local_01 error: Timeout waiting for ssh access
2016-04-14 12:29:03,675 INFO nodepool.NodePool: Deleted jenkins node id: 28247
2016-04-14 12:29:12,274 INFO nodepool.NodePool: Deleted node id: 28247
2016-04-14 12:29:13,424 INFO nodepool.NodePool: Need to launch 1 d-p-c nodes for jenkins1 on local_01
2016-04-14 12:29:13,457 INFO nodepool.NodeLauncher: Creating server with hostname d-p-c-local_01-28248 in local_01 from image dpc for node id: 28248
2016-04-14 12:33:15,558 ERROR nodepool.utils: Exception while testing ssh access:
Traceback (most recent call last):
  File "/usr/local/lib/python2.7/dist-packages/nodepool/nodeutils.py", line 55, in ssh_connect
    client = SSHClient(ip, username, **connect_kwargs)
  File "/usr/local/lib/python2.7/dist-packages/nodepool/sshclient.py", line 30, in __init__
    key_filename=key_filename)
  File "/usr/local/lib/python2.7/dist-packages/paramiko/client.py", line 292, in connect
    retry_on_signal(lambda: sock.connect(addr))
  File "/usr/local/lib/python2.7/dist-packages/paramiko/util.py", line 270, in retry_on_signal
    return function()
  File "/usr/local/lib/python2.7/dist-packages/paramiko/client.py", line 292, in <lambda>
    retry_on_signal(lambda: sock.connect(addr))
  File "/usr/lib/python2.7/socket.py", line 224, in meth
    return getattr(self._sock,name)(*args)
error: [Errno 110] Connection timed out
2016-04-14 12:33:17,562 ERROR nodepool.NodeLauncher: Timeout launching node id: 28248 in provider: local_01 error: Timeout waiting for ssh access
2016-04-14 12:33:17,623 INFO nodepool.NodePool: Deleted jenkins node id: 28248
2016-04-14 12:33:24,765 INFO nodepool.NodePool: Need to launch 1 d-p-c nodes for jenkins1 on local_01
2016-04-14 12:33:24,797 INFO nodepool.NodeLauncher: Creating server with hostname d-p-c-local_01-28249 in local_01 from image dpc for node id: 28249
2016-04-14 12:33:27,333 INFO nodepool.NodePool: Deleted node id: 28248
2016-04-14 12:37:24,774 ERROR nodepool.utils: Exception while testing ssh access:
Traceback (most recent call last):
  File "/usr/local/lib/python2.7/dist-packages/nodepool/nodeutils.py", line 55, in ssh_connect
    client = SSHClient(ip, username, **connect_kwargs)
  File "/usr/local/lib/python2.7/dist-packages/nodepool/sshclient.py", line 30, in __init__
    key_filename=key_filename)
  File "/usr/local/lib/python2.7/dist-packages/paramiko/client.py", line 292, in connect
    retry_on_signal(lambda: sock.connect(addr))
  File "/usr/local/lib/python2.7/dist-packages/paramiko/util.py", line 270, in retry_on_signal
    return function()
  File "/usr/local/lib/python2.7/dist-packages/paramiko/client.py", line 292, in <lambda>
    retry_on_signal(lambda: sock.connect(addr))
  File "/usr/lib/python2.7/socket.py", line 224, in meth
    return getattr(self._sock,name)(*args)
error: [Errno 110] Connection timed out
2016-04-14 12:37:26,780 ERROR nodepool.NodeLauncher: Timeout launching node id: 28249 in provider: local_01 error: Timeout waiting for ssh access
2016-04-14 12:37:26,843 INFO nodepool.NodePool: Deleted jenkins node id: 28249
2016-04-14 12:37:36,071 INFO nodepool.NodePool: Need to launch 1 d-p-c nodes for jenkins1 on local_01
2016-04-14 12:37:36,112 INFO nodepool.NodeLauncher: Creating server with hostname d-p-c-local_01-28250 in local_01 from image dpc for node id: 28250
2016-04-14 12:37:38,226 INFO nodepool.NodePool: Deleted node id: 28249
